Workbook

Sheet Raw Data_modified
T1: Tractor | V1: Combine Harvester | Y1: Tractor | AA1: Combine Harvester
A2: N° | B2: Dép | C2: Nom de l'Entreprise | D2: Privé/Union | E2: Type materiel | F2: Localité | G2: Zone SAED | H2: Chef de l'Entreprise | I2: Contact | J2: Marque | K2: Modèle | L2: Numéro de série | M2: Etat | N2: Année acquisition | O2: Puissance | P2: Offset/ Charrue | Q2: Etat | R2: Année acquisition | T2: Service Provider (Extract) | U2: Service Provider (List) | V2: Service Provider (Extract) | W2: Service Provider (List) | Y2: List of Service provider | Z2: Form | AA2: List of Service provider | AB2: Form
A3: 1 | B3: Kanel | C3: Abdoulaye Bocar NDIAYE | D3: Private | E3: Tracteur | F3: Wouro Sidy | G3: Wouro Sidy | H3: Abdoulaye Bocar NDIAYE | I3: 771654286 | J3: TAFE | K3: 1002 4WD | M3: Function | N3: 2019 | O3: 100 | P3: Offset | Q3: Function | R3: 2019 | T3: {=IFERROR(_xlfn._xlws.FILTER(C3,E3="Tractor"),"")} | U3: {=_xlfn.UNIQUE(T3:T94)} | V3: {=IFERROR(_xlfn._xlws.FILTER(C3,#REF!="Combine Harvester"),"")} | W3: {=_xlfn.UNIQUE(V3:V94)} | Y3: Oumar Aguibou SOW | Z3: =_xlfn.XLOOKUP(Y3,$C$3:$C$94,$D$3:$D$94,"") -> Union | AA3: Union Hydraulique de Hamady Ounaré | AB3: =_xlfn.XLOOKUP(AA3,$C$3:$C$94,$D$3:$D$94,"") -> Union
A4: 2 | B4: Matam | C4: Abdoulaye Djiby THIAM | D4: Private | E4: Tracteur | F4: Nabadji Civol | G4: Nabadji | H4: Abdoulaye Djiby THIAM | I4: 776365447 | J4: TAFE | K4: 1002 4WD | M4: Function | N4: 2019 | O4: 100 | P4: Offset | Q4: Function | R4: 2019 | T4: {=IFERROR(_xlfn._xlws.FILTER(C4,E4="Tractor"),"")} | V4: {=IFERROR(_xlfn._xlws.FILTER(C4,#REF!="Combine Harvester"),"")} | Y4: Union des GIE de Diamoungeul 1 et 2 | Z4: =_xlfn.XLOOKUP(Y4,$C$3:$C$94,$D$3:$D$94,"") -> Union | AA4: GIE Dagano | AB4: =_xlfn.XLOOKUP(AA4,$C$3:$C$94,$D$3:$D$94,"") -> Private
A5: 3 | B5: Kanel | C5: Abou DIAW | D5: Private | E5: Tracteur | F5: Ounaré | G5: Wouro Sidy | H5: Abou DIAW | I5: 776143821 | J5: TAFE | K5: 1002 4WD | M5: Function | N5: 2019 | O5: 100 | P5: Offset | Q5: Function | R5: 2019 | T5: {=IFERROR(_xlfn._xlws.FILTER(C5,E5="Tractor"),"")} | V5: {=IFERROR(_xlfn._xlws.FILTER(C5,#REF!="Combine Harvester"),"")} | Y5: DIENG et Fammile | Z5: =_xlfn.XLOOKUP(Y5,$C$3:$C$94,$D$3:$D$94,"") -> Private | AA5: Union du Casier Doumga Ouro Thierno | AB5: =_xlfn.XLOOKUP(AA5,$C$3:$C$94,$D$3:$D$94,"") -> Union
A6: 4 | B6: Matam | C6: Comité de Gestion de Koundel 3 | D6: Private | E6: Tracteur | F6: Nabadji Civol | G6: Nabadji | H6: Abdoulaye Saidou Diaw | I6: 774077602 | J6: VALTRA | K6: BH 165 | M6: Function | N6: 2015 | O6: Moins de 100 | P6: Offset | Q6: Function | R6: 2015 | T6: {=IFERROR(_xlfn._xlws.FILTER(C6,E6="Tractor"),"")} | V6: {=IFERROR(_xlfn._xlws.FILTER(C6,#REF!="Combine Harvester"),"")} | Y6: Harouna | Z6: =_xlfn.XLOOKUP(Y6,$C$3:$C$94,$D$3:$D$94,"") -> Private | AA6: Makhana Diéri | AB6: =_xlfn.XLOOKUP(AA6,$C$3:$C$94,$D$3:$D$94,"") -> Private
A7: 5 | B7: Kanel | C7: Aboubacry Goby BASSOUM | D7: Private | E7: Tracteur | F7: Kanel | G7: Wouro Sidy | H7: Aboubacry Goby BASSOUM | I7: 77 564 25 33 | J7: TAFE | K7: 1002 4WD | M7: Function | N7: 2019 | O7: 100 | P7: Offset | Q7: Function | R7: 2019 | T7: {=IFERROR(_xlfn._xlws.FILTER(C7,E7="Tractor"),"")} | V7: {=IFERROR(_xlfn._xlws.FILTER(C7,#REF!="Combine Harvester"),"")} | Y7: Samba KANE | Z7: =_xlfn.XLOOKUP(Y7,$C$3:$C$94,$D$3:$D$94,"") -> Private | AA7: Union Hydraulique de Kobilo | AB7: =_xlfn.XLOOKUP(AA7,$C$3:$C$94,$D$3:$D$94,"") -> Union
A8: 6 | B8: Matam | C8: Comité de Gestion de Woudourou 1 | D8: Private | E8: Tracteur | F8: Nabadji Civol | G8: Nabadji | H8: Seydou Kane | I8: 77 617 00 25 77 555 77 98 | J8: VALTRA | K8: BM125 I | M8: Function | N8: 2015 | O8: Moins de 100 | P8: Offset | Q8: Function | R8: 2015 | T8: {=IFERROR(_xlfn._xlws.FILTER(C8,E8="Tractor"),"")} | V8: {=IFERROR(_xlfn._xlws.FILTER(C8,#REF!="Combine Harvester"),"")} | Y8: Union Hydraulique de Dolol/Wodobéré | Z8: =_xlfn.XLOOKUP(Y8,$C$3:$C$94,$D$3:$D$94,"") -> Union | AA8: Union Régionale des Interprofessionnels de Semences (URIS) | AB8: =_xlfn.XLOOKUP(AA8,$C$3:$C$94,$D$3:$D$94,"") -> Private
A9: 7 | B9: Kanel | C9: Association des Agriculteurs de Waoundé | D9: Private | E9: Tracteur | F9: Waoundé | G9: Orkadiere | H9: Samba Camara | I9: 77 562 49 16 | J9: John Deere | K9: 6125 | L9: D | M9: Function | N9: 2016 | O9: 125 | P9: Offset | Q9: Function | R9: 2016 | T9: {=IFERROR(_xlfn._xlws.FILTER(C9,E9="Tractor"),"")} | V9: {=IFERROR(_xlfn._xlws.FILTER(C9,#REF!="Combine Harvester"),"")} | Y9: Union Hydraulique de Hamady Ounaré | Z9: =_xlfn.XLOOKUP(Y9,$C$3:$C$94,$D$3:$D$94,"") -> Union | AA9: GIE Townde | AB9: =_xlfn.XLOOKUP(AA9,$C$3:$C$94,$D$3:$D$94,"") -> Private
A10: 8 | B10: Matam | C10: Déworoy Jokkéré Endam | D10: Private | E10: Tracteur | F10: Nabadji Civol | G10: Nabadji | H10: Arona Sall | I10: 78 496 44 02 | J10: John Deere | K10: 6125 | L10: D | M10: Function | N10: 2016 | O10: 125 | P10: Offset | Q10: Function | R10: 2016 | T10: {=IFERROR(_xlfn._xlws.FILTER(C10,E10="Tractor"),"")} | V10: {=IFERROR(_xlfn._xlws.FILTER(C10,#REF!="Combine Harvester"),"")} | Y10: Abdoulaye KANE | Z10: =_xlfn.XLOOKUP(Y10,$C$3:$C$94,$D$3:$D$94,"") -> Private | AA10: Union Hydraulique de Ndouloumadji | AB10: =_xlfn.XLOOKUP(AA10,$C$3:$C$94,$D$3:$D$94,"") -> Union
A11: 9 | B11: Kanel | C11: Bocar DAFF | D11: Private | E11: Tracteur | F11: Ndendory | G11: Ndendory | H11: Bocar DAFF | I11: 775759153 | J11: TAFE | K11: 1002 4WD | M11: Function | N11: 2019 | O11: 100 | P11: Offset | Q11: Function | R11: 2019 | T11: {=IFERROR(_xlfn._xlws.FILTER(C11,E11="Tractor"),"")} | V11: {=IFERROR(_xlfn._xlws.FILTER(C11,#REF!="Combine Harvester"),"")} | Y11: Diango DIABY | Z11: =_xlfn.XLOOKUP(Y11,$C$3:$C$94,$D$3:$D$94,"") -> Private
A12: 10 | B12: Matam | C12: Dieynaba Abdoul SY | D12: Private | E12: Tracteur | F12: Agnam Civol | G12: Agnam/Oréfondé | H12: Dieynaba Abdoul SY | I12: 77120989 | J12: TAFE | K12: 1002 4WD | M12: Function | N12: 2019 | O12: 100 | P12: Offset | Q12: Function | R12: 2019 | T12: {=IFERROR(_xlfn._xlws.FILTER(C12,E12="Tractor"),"")} | V12: {=IFERROR(_xlfn._xlws.FILTER(C12,#REF!="Combine Harvester"),"")} | Y12: GIE Alla Lewy | Z12: =_xlfn.XLOOKUP(Y12,$C$3:$C$94,$D$3:$D$94,"") -> Private
A13: 11 | B13: Kanel | C13: Diango DIABY | D13: Private | E13: Tracteur | F13: Hamady Ounaré | G13: Ndendory | H13: Diango DIABY | I13: 776574960 | J13: TAFE | K13: 1002 4WD | M13: Function | N13: 2019 | O13: 100 | P13: Offset | Q13: Function | R13: 2019 | T13: {=IFERROR(_xlfn._xlws.FILTER(C13,E13="Tractor"),"")} | V13: {=IFERROR(_xlfn._xlws.FILTER(C13,#REF!="Combine Harvester"),"")} | Y13: GIE Ngano | Z13: =_xlfn.XLOOKUP(Y13,$C$3:$C$94,$D$3:$D$94,"") -> Private
A14: 12 | B14: Matam | C14: GIE Alphala | D14: Private | E14: Tracteur | F14: Nabadji Civol | G14: Nabadji | H14: Abdoulaye Gassama | I14: 77 966 50 84 | J14: John Deere | K14: 6125 | L14: D | M14: Function | N14: 2016 | O14: 125 | P14: Offset | Q14: Function | R14: 2016 | T14: {=IFERROR(_xlfn._xlws.FILTER(C14,E14="Tractor"),"")} | V14: {=IFERROR(_xlfn._xlws.FILTER(C14,#REF!="Combine Harvester"),"")} | Y14: Amadou KANE | Z14: =_xlfn.XLOOKUP(Y14,$C$3:$C$94,$D$3:$D$94,"") -> Private
A15: 13 | B15: Kanel | C15: GIE Alla Lewy | D15: Private | E15: Tracteur | F15: Hamady Ounaré | G15: Ndendory | H15: Souleymane Diagana | I15: 77 671 02 95 | J15: VALTRA | K15: BH 165 | M15: Function | N15: 2015 | O15: Moins de 100 | P15: Offset | Q15: Function | R15: 2015 | T15: {=IFERROR(_xlfn._xlws.FILTER(C15,E15="Tractor"),"")} | V15: {=IFERROR(_xlfn._xlws.FILTER(C15,#REF!="Combine Harvester"),"")} | Y15: Bocar DAFF | Z15: =_xlfn.XLOOKUP(Y15,$C$3:$C$94,$D$3:$D$94,"") -> Private
A16: 14 | B16: Matam | C16: GIE Dowourou | D16: Private | E16: Tracteur | F16: Agnam Civol | G16: Agnam/Oréfondé | H16: Abdou Aziz Diop | I16: 77 350 56 60 | J16: John Deere | K16: 6125 | L16: D | M16: Function | N16: 2016 | O16: 125 | P16: Offset | Q16: Function | R16: 2016 | T16: {=IFERROR(_xlfn._xlws.FILTER(C16,E16="Tractor"),"")} | V16: {=IFERROR(_xlfn._xlws.FILTER(C16,#REF!="Combine Harvester"),"")} | Y16: Thierno Hameth SALL | Z16: =_xlfn.XLOOKUP(Y16,$C$3:$C$94,$D$3:$D$94,"") -> Private
A17: 15 | B17: Kanel | C17: Union Hydraulique de Hamady Ounaré | D17: Union | E17: Tracteur | F17: Hamady Ounaré | G17: Ndendory | H17: Abdoulaye KANE | I17: 77 632 39 35 | J17: CASE | K17: 75 | M17: Function | N17: N/A | Q17: N/A | T17: {=IFERROR(_xlfn._xlws.FILTER(C17,E17="Tractor"),"")} | V17: {=IFERROR(_xlfn._xlws.FILTER(C17,#REF!="Combine Harvester"),"")} | Y17: Talla | Z17: =_xlfn.XLOOKUP(Y17,$C$3:$C$94,$D$3:$D$94,"") -> Private
A18: 16 | B18: Matam | C18: GIE Fadigada | D18: Private | E18: Tracteur | F18: Dabia | G18: Dabia | H18: Mamadou Kane | I18: 77 563 64 97 | J18: John Deere | K18: 6125 | L18: D | M18: Function | N18: 2016 | O18: 125 | P18: Offset | Q18: Function | R18: 2016 | T18: {=IFERROR(_xlfn._xlws.FILTER(C18,E18="Tractor"),"")} | V18: {=IFERROR(_xlfn._xlws.FILTER(C18,#REF!="Combine Harvester"),"")} | Y18: Mamadou TALL | Z18: =_xlfn.XLOOKUP(Y18,$C$3:$C$94,$D$3:$D$94,"") -> Private
A19: 17 | B19: Kanel | C19: GIE Dagano | D19: Private | E19: Tracteur | F19: Orkadiéré | G19: Orkadiere | H19: Arona Dagano | I19: 77 693 06 56 | J19: John Deere | K19: 6125 | L19: D | M19: Breakdown | N19: 2008 | O19: 125 | P19: Offset | Q19: Function | R19: 2008 | T19: {=IFERROR(_xlfn._xlws.FILTER(C19,E19="Tractor"),"")} | V19: {=IFERROR(_xlfn._xlws.FILTER(C19,#REF!="Combine Harvester"),"")} | Y19: Docteur DAFF | Z19: =_xlfn.XLOOKUP(Y19,$C$3:$C$94,$D$3:$D$94,"") -> Private
A20: 18 | B20: Matam | C20: GIE Moyyere Thierno Yaya | D20: Private | E20: Tracteur | F20: Nabadji Civol | G20: Nabadji | H20: Oumar Deme | I20: 77 643 65 61 | J20: John Deere | K20: 6125 | L20: D | M20: Function | N20: 2016 | O20: 125 | P20: Offset | Q20: Function | R20: 2016 | T20: {=IFERROR(_xlfn._xlws.FILTER(C20,E20="Tractor"),"")} | V20: {=IFERROR(_xlfn._xlws.FILTER(C20,#REF!="Combine Harvester"),"")} | Y20: Moussa BEYTA | Z20: =_xlfn.XLOOKUP(Y20,$C$3:$C$94,$D$3:$D$94,"") -> Private
A21: 19 | B21: Kanel | C21: GIE Dagano | D21: Private | E21: Tracteur | F21: Orkadiéré | G21: Orkadiere | H21: Arona Dagano | I21: 78 693 06 56 | J21: John Deere | K21: 6125 | L21: D | M21: Breakdown | N21: 2009 | O21: 125 | P21: Offset | Q21: Function | R21: 2009 | T21: {=IFERROR(_xlfn._xlws.FILTER(C21,E21="Tractor"),"")} | V21: {=IFERROR(_xlfn._xlws.FILTER(C21,#REF!="Combine Harvester"),"")} | Y21: GIE Dembacané 2 | Z21: =_xlfn.XLOOKUP(Y21,$C$3:$C$94,$D$3:$D$94,"") -> Private
A22: 20 | B22: Matam | C22: GIE Ndéma | D22: Private | E22: Tracteur | F22: Nabadji Civol | G22: Nabadji | H22: El Hadji Malick Dème | I22: 77 551 73 84 | J22: John Deere | K22: 6125 | L22: D | M22: Function | N22: 2016 | O22: 125 | P22: Offset | Q22: Function | R22: 2016 | T22: {=IFERROR(_xlfn._xlws.FILTER(C22,E22="Tractor"),"")} | V22: {=IFERROR(_xlfn._xlws.FILTER(C22,#REF!="Combine Harvester"),"")} | Y22: GIE Nourou Cheikh Moussa Camara | Z22: =_xlfn.XLOOKUP(Y22,$C$3:$C$94,$D$3:$D$94,"") -> Private
A23: 21 | B23: Kanel | C23: GIE Dagano | D23: Private | E23: Tracteur | F23: Orkadiéré | G23: Orkadiere | H23: Arona Dagano | I23: 79 693 06 56 | J23: John Deere | K23: 6125 | L23: D | M23: Breakdown | N23: 2008 | O23: 125 | P23: Offset | Q23: Function | R23: 2008 | T23: {=IFERROR(_xlfn._xlws.FILTER(C23,E23="Tractor"),"")} | V23: {=IFERROR(_xlfn._xlws.FILTER(C23,#REF!="Combine Harvester"),"")} | Y23: GIE Dagano | Z23: =_xlfn.XLOOKUP(Y23,$C$3:$C$94,$D$3:$D$94,"") -> Private
A24: 22 | B24: Matam | C24: GIE Raky Ganna | D24: Private | E24: Tracteur | F24: Matam | G24: Matam/ogo | H24: Abou Thioub | I24: 77 542 42 88 | J24: VALTRA | K24: 6125 | M24: Function | N24: 2015 | O24: Moins de 100 | P24: Offset | Q24: Function | R24: 2015 | T24: {=IFERROR(_xlfn._xlws.FILTER(C24,E24="Tractor"),"")} | V24: {=IFERROR(_xlfn._xlws.FILTER(C24,#REF!="Combine Harvester"),"")} | Y24: GIE Ganguel | Z24: =_xlfn.XLOOKUP(Y24,$C$3:$C$94,$D$3:$D$94,"") -> Private
A25: 23 | B25: Kanel | C25: GIE Dagano | D25: Private | E25: Tracteur | F25: Orkadiéré | G25: Orkadiere | H25: Arona Dagano | I25: 80 693 06 56 | J25: John Deere | K25: 5410 | M25: Breakdown | N25: 2010 | O25: 125 | P25: Offset | Q25: Function | R25: 2010 | T25: {=IFERROR(_xlfn._xlws.FILTER(C25,E25="Tractor"),"")} | V25: {=IFERROR(_xlfn._xlws.FILTER(C25,#REF!="Combine Harvester"),"")} | Y25: GIE Jokkéré Endam Wendou Bosséabé | Z25: =_xlfn.XLOOKUP(Y25,$C$3:$C$94,$D$3:$D$94,"") -> Private
A26: 24 | B26: Matam | C26: GIE Raky Ganna | D26: Private | E26: Tracteur | F26: Matam | G26: Matam/ogo | H26: Abou Thioub | I26: 78 542 42 88 | J26: John Deere | K26: 6125 | L26: D | M26: Function | N26: 2016 | O26: 125 | P26: Offset | Q26: Function | R26: 2016 | T26: {=IFERROR(_xlfn._xlws.FILTER(C26,E26="Tractor"),"")} | V26: {=IFERROR(_xlfn._xlws.FILTER(C26,#REF!="Combine Harvester"),"")} | Y26: GIE PiP Balel | Z26: =_xlfn.XLOOKUP(Y26,$C$3:$C$94,$D$3:$D$94,"") -> Private
A27: 25 | B27: Kanel | C27: GIE Dagano | D27: Private | E27: Tracteur | F27: Orkadiéré | G27: Orkadiere | H27: Arona Dagano | I27: 81 693 06 56 | J27: John Deere | K27: 5205 | M27: Breakdown | N27: 2008 | O27: 125 | P27: Offset | Q27: Function | R27: 2008 | T27: {=IFERROR(_xlfn._xlws.FILTER(C27,E27="Tractor"),"")} | V27: {=IFERROR(_xlfn._xlws.FILTER(C27,#REF!="Combine Harvester"),"")} | Y27: Mbegnouga et frères | Z27: =_xlfn.XLOOKUP(Y27,$C$3:$C$94,$D$3:$D$94,"") -> Private
A28: 26 | B28: Matam | C28: GIE Sognane et Frères | D28: Private | E28: Tracteur | F28: Nabadji Civol | G28: Nabadji | H28: Maissa Yero Sognane | I28: 77 609 42 72 | J28: John Deere | K28: 6125 | L28: D | M28: Function | N28: 2016 | O28: 125 | P28: Offset | Q28: Function | R28: 2016 | T28: {=IFERROR(_xlfn._xlws.FILTER(C28,E28="Tractor"),"")} | V28: {=IFERROR(_xlfn._xlws.FILTER(C28,#REF!="Combine Harvester"),"")} | Y28: Union Orkadiéré | Z28: =_xlfn.XLOOKUP(Y28,$C$3:$C$94,$D$3:$D$94,"") -> Union
A29: 27 | B29: Kanel | C29: GIE Dagano | D29: Private | E29: Tracteur | F29: Orkadiéré | G29: Orkadiere | H29: Arona Dagano | I29: 82 693 06 56 | J29: John Deere | K29: 4440 | M29: Breakdown | N29: 2009 | O29: 125 | P29: Offset | Q29: Function | R29: 2009 | T29: {=IFERROR(_xlfn._xlws.FILTER(C29,E29="Tractor"),"")} | V29: {=IFERROR(_xlfn._xlws.FILTER(C29,#REF!="Combine Harvester"),"")} | Y29: Famille Mbégnouga | Z29: =_xlfn.XLOOKUP(Y29,$C$3:$C$94,$D$3:$D$94,"") -> Private
A30: 28 | B30: Matam | C30: GIE Townde | D30: Private | E30: Tracteur | F30: Nabadji Civol | G30: Nabadji | H30: Sidy Dème | I30: 77 325 78 39 | J30: John Deere | K30: 6125 | M30: Function | N30: 2016 | O30: 125 | P30: Offset | Q30: Function | R30: 2016 | T30: {=IFERROR(_xlfn._xlws.FILTER(C30,E30="Tractor"),"")} | V30: {=IFERROR(_xlfn._xlws.FILTER(C30,#REF!="Combine Harvester"),"")} | Y30: Thierno Abdoul BA | Z30: =_xlfn.XLOOKUP(Y30,$C$3:$C$94,$D$3:$D$94,"") -> Private
A31: 29 | B31: Kanel | C31: GIE Dagano | D31: Private | E31: Tracteur | F31: Orkadiéré | G31: Orkadiere | H31: Arona Dagano | I31: 83 693 06 56 | J31: John Deere | K31: 553 WIX | M31: Function | N31: 2010 | O31: Moins de 100 | P31: Offset | Q31: Function | R31: 2010 | T31: {=IFERROR(_xlfn._xlws.FILTER(C31,E31="Tractor"),"")} | V31: {=IFERROR(_xlfn._xlws.FILTER(C31,#REF!="Combine Harvester"),"")} | Y31: Samba DIENG | Z31: =_xlfn.XLOOKUP(Y31,$C$3:$C$94,$D$3:$D$94,"") -> Private
A32: 30 | B32: Matam | C32: GIE Townde | D32: Private | E32: Tracteur | F32: Nabadji Civol | G32: Nabadji | H32: Sidy Dème | I32: 78 325 78 39 | J32: TAFE | K32: 1002 4WD | M32: Function | N32: 2017 | O32: 115 | P32: Offset | Q32: Function | R32: 2017 | T32: {=IFERROR(_xlfn._xlws.FILTER(C32,E32="Tractor"),"")} | V32: {=IFERROR(_xlfn._xlws.FILTER(C32,#REF!="Combine Harvester"),"")} | Y32: Association des Agriculteurs de Waoundé | Z32: =_xlfn.XLOOKUP(Y32,$C$3:$C$94,$D$3:$D$94,"") -> Private
A33: 31 | B33: Kanel | C33: GIE Dagano | D33: Private | E33: Tracteur | F33: Orkadiéré | G33: Orkadiere | H33: Arona Dagano | I33: 84 693 06 56 | J33: John Deere | K33: 5410 | M33: Function | N33: 2010 | O33: Moins de 100 | P33: Offset | Q33: Function | R33: 2010 | T33: {=IFERROR(_xlfn._xlws.FILTER(C33,E33="Tractor"),"")} | V33: {=IFERROR(_xlfn._xlws.FILTER(C33,#REF!="Combine Harvester"),"")} | Y33: GIE Waoundé 1 | Z33: =_xlfn.XLOOKUP(Y33,$C$3:$C$94,$D$3:$D$94,"") -> Private
A34: 32 | B34: Matam | C34: GIE Yarnde | D34: Private | E34: Tracteur | F34: Bokidiawé | G34: Bokidiawé | H34: Bokar KANE | I34: 77 563 34 21 | J34: John Deere | K34: 6125 | M34: Function | N34: 2016 | O34: 125 | P34: Offset | Q34: Function | R34: 2016 | T34: {=IFERROR(_xlfn._xlws.FILTER(C34,E34="Tractor"),"")} | V34: {=IFERROR(_xlfn._xlws.FILTER(C34,#REF!="Combine Harvester"),"")} | Y34: BARRO | Z34: =_xlfn.XLOOKUP(Y34,$C$3:$C$94,$D$3:$D$94,"") -> Private
A35: 33 | B35: Kanel | C35: GIE Dagano | D35: Private | E35: Tracteur | F35: Orkadiéré | G35: Orkadiere | H35: Arona Dagano | I35: 85 693 06 56 | J35: John Deere | K35: 6125 | M35: Function | N35: 2010 | O35: 125 | P35: Offset | Q35: Function | R35: 2010 | T35: {=IFERROR(_xlfn._xlws.FILTER(C35,E35="Tractor"),"")} | V35: {=IFERROR(_xlfn._xlws.FILTER(C35,#REF!="Combine Harvester"),"")} | Y35: Mamel DEME | Z35: =_xlfn.XLOOKUP(Y35,$C$3:$C$94,$D$3:$D$94,"") -> Private
A36: 34 | B36: Matam | C36: Harouna DIOP | D36: Union | E36: Tracteur | F36: Nabadji Civol | G36: Nabadji | H36: Harouna DIOP | I36: 775566197 | J36: TAFE | K36: 1002 4WD | M36: Function | N36: 2019 | O36: 100 | P36: Offset | Q36: Function | R36: 2019 | T36: {=IFERROR(_xlfn._xlws.FILTER(C36,E36="Tractor"),"")} | V36: {=IFERROR(_xlfn._xlws.FILTER(C36,#REF!="Combine Harvester"),"")} | Y36: Kisma Delba SOW | Z36: =_xlfn.XLOOKUP(Y36,$C$3:$C$94,$D$3:$D$94,"") -> Private
A37: 35 | B37: Kanel | C37: GIE Dagano | D37: Private | E37: Tracteur | F37: Orkadiéré | G37: Orkadiere | H37: Arona Dagano | I37: 86 693 06 56 | J37: John Deere | K37: 6125 | M37: Function | N37: 2010 | O37: 125 | P37: Offset | Q37: Function | R37: 2010 | T37: {=IFERROR(_xlfn._xlws.FILTER(C37,E37="Tractor"),"")} | V37: {=IFERROR(_xlfn._xlws.FILTER(C37,#REF!="Combine Harvester"),"")} | Y37: Aboubacry Goby BASSOUM | Z37: =_xlfn.XLOOKUP(Y37,$C$3:$C$94,$D$3:$D$94,"") -> Private
A38: 36 | B38: Matam | C38: Mamadou BA | D38: Private | E38: Tracteur | F38: Danthiady | G38: Matam/ogo | H38: Mamadou BA | I38: 776545626 | J38: TAFE | K38: 1002 4WD | M38: Function | N38: 2019 | O38: 100 | P38: Offset | Q38: Function | R38: 2019 | T38: {=IFERROR(_xlfn._xlws.FILTER(C38,E38="Tractor"),"")} | V38: {=IFERROR(_xlfn._xlws.FILTER(C38,#REF!="Combine Harvester"),"")} | Y38: Kadiatou BASSOUM | Z38: =_xlfn.XLOOKUP(Y38,$C$3:$C$94,$D$3:$D$94,"") -> Private
A39: 37 | B39: Kanel | C39: GIE Dembacané 2 | D39: Private | E39: Tracteur | F39: Dembacané | G39: Orkadiere | H39: Baye Soumare | I39: 772769932 | J39: VALTRA | K39: A750 | M39: Function | N39: 2015 | O39: Moins de 100 | P39: Offset | Q39: Function | R39: 2015 | T39: {=IFERROR(_xlfn._xlws.FILTER(C39,E39="Tractor"),"")} | V39: {=IFERROR(_xlfn._xlws.FILTER(C39,#REF!="Combine Harvester"),"")} | Y39: Mamadou Abdoulaye MEYTY | Z39: =_xlfn.XLOOKUP(Y39,$C$3:$C$94,$D$3:$D$94,"") -> Private
A40: 38 | B40: Matam | C40: Mamadou Lamine LY | D40: Private | E40: Tracteur | F40: Bokidiawé | G40: Bokidiawé | H40: Mamadou Lamine LY | I40: 776086580 | J40: TAFE | K40: 1002 4WD | M40: Function | N40: 2019 | O40: 100 | P40: Offset | Q40: Function | R40: 2019 | T40: {=IFERROR(_xlfn._xlws.FILTER(C40,E40="Tractor"),"")} | V40: {=IFERROR(_xlfn._xlws.FILTER(C40,#REF!="Combine Harvester"),"")} | Y40: Abou DIAW | Z40: =_xlfn.XLOOKUP(Y40,$C$3:$C$94,$D$3:$D$94,"") -> Private
...

Sheet Raw Data
Z1: Tractor | AB1: Combine Harvester | AE1: Tractor | AG1: Combine Harvester
A2: N° | B2: Dép | C2: Nom de l'Entreprise | D2: Privé/Union | E2: Type materiel | G2: Localité | H2: Zone SAED | I2: Chef de l'Entreprise | J2: Contact | K2: Marque | L2: Modelé | M2: Numéro de série | N2: Tracteur Puissance | O2: Tracteur Etat | P2: Année acquisition | Q2: Offset/ Charrue | R2: Etat | S2: Année acquisition | T2: Modelé | U2: Numéro de série | V2: MB Puissance | W2: MB Etat | X2: Année acquisition | Z2: Service Provider (Extract) | AA2: Service Provider (List) | AB2: Service Provider (Extract) | AC2: Service Provider (List) | AE2: List of Service provider | AF2: Form | AG2: List of Service provider | AH2: Form
A3: 1 | B3: Kanel | C3: Abdoulaye Bocar NDIAYE | D3: Private | E3: Tractor | G3: Wouro Sidy | H3: Wouro Sidy | I3: Abdoulaye Bocar NDIAYE | J3: 771654286 | K3: TAFE | N3: 100 | O3: Function | P3: 2019 | Q3: Offset | R3: Function | S3: 2019 | Z3: {=IFERROR(_xlfn._xlws.FILTER(C3,E3="Tractor"),"")} -> Abdoulaye Bocar NDIAYE | AA3: {=_xlfn.UNIQUE(Z3:Z94)} -> Abdoulaye Bocar NDIAYE | AB3: {=IFERROR(_xlfn._xlws.FILTER(C3,F3="Combine Harvester"),"")} | AC3: {=_xlfn.UNIQUE(AB3:AB94)} | AE3: Oumar Aguibou SOW | AF3: =_xlfn.XLOOKUP(AE3,$C$3:$C$94,$D$3:$D$94,"") -> Union | AG3: Union Hydraulique de Hamady Ounaré | AH3: =_xlfn.XLOOKUP(AG3,$C$3:$C$94,$D$3:$D$94,"") -> Union
A4: 1 | B4: Matam | C4: Abdoulaye Djiby THIAM | D4: Private | E4: Tractor | G4: Nabadji Civol | H4: Nabadji | I4: Abdoulaye Djiby THIAM | J4: 776365447 | K4: TAFE | N4: 100 | O4: Function | P4: 2019 | Q4: Offset | R4: Function | S4: 2019 | Z4: {=IFERROR(_xlfn._xlws.FILTER(C4,E4="Tractor"),"")} -> Abdoulaye Djiby THIAM | AA4: Abdoulaye Djiby THIAM | AB4: {=IFERROR(_xlfn._xlws.FILTER(C4,F4="Combine Harvester"),"")} | AC4: GIE Dagano | AE4: Union des GIE de Diamoungeul 1 et 2 | AF4: =_xlfn.XLOOKUP(AE4,$C$3:$C$94,$D$3:$D$94,"") -> Union | AG4: GIE Dagano | AH4: =_xlfn.XLOOKUP(AG4,$C$3:$C$94,$D$3:$D$94,"") -> Private
A5: 2 | B5: Kanel | C5: Abou DIAW | D5: Private | E5: Tractor | G5: Ounaré | H5: Wouro Sidy | I5: Abou DIAW | J5: 776143821 | K5: TAFE | N5: 100 | O5: Function | P5: 2019 | Q5: Offset | R5: Function | S5: 2019 | Z5: {=IFERROR(_xlfn._xlws.FILTER(C5,E5="Tractor"),"")} -> Abou DIAW | AA5: Abou DIAW | AB5: {=IFERROR(_xlfn._xlws.FILTER(C5,F5="Combine Harvester"),"")} | AC5: GIE Townde | AE5: DIENG et Fammile | AF5: =_xlfn.XLOOKUP(AE5,$C$3:$C$94,$D$3:$D$94,"") -> Private | AG5: Union du Casier Doumga Ouro Thierno | AH5: =_xlfn.XLOOKUP(AG5,$C$3:$C$94,$D$3:$D$94,"") -> Union
A6: 2 | B6: Matam | C6: Comité de Gestion de Koundel 3 | D6: Private | E6: Tractor | G6: Nabadji Civol | H6: Nabadji | I6: Abdoulaye Saidou Diaw | J6: 774077602 | K6: VALTRA | N6: Moins de 100 | O6: Function | P6: 2015 | Q6: Offset | R6: Function | S6: 2015 | Z6: {=IFERROR(_xlfn._xlws.FILTER(C6,E6="Tractor"),"")} -> Comité de Gestion de Koundel 3 | AA6: Comité de Gestion de Koundel 3 | AB6: {=IFERROR(_xlfn._xlws.FILTER(C6,F6="Combine Harvester"),"")} | AC6: Union du Casier Doumga Ouro Thierno | AE6: Harouna | AF6: =_xlfn.XLOOKUP(AE6,$C$3:$C$94,$D$3:$D$94,"") -> Private | AG6: Makhana Diéri | AH6: =_xlfn.XLOOKUP(AG6,$C$3:$C$94,$D$3:$D$94,"") -> Private
A7: 3 | B7: Kanel | C7: Aboubacry Goby BASSOUM | D7: Private | E7: Tractor | G7: Kanel | H7: Wouro Sidy | I7: Aboubacry Goby BASSOUM | J7: 77 564 25 33 | K7: TAFE | N7: 100 | O7: Function | P7: 2019 | Q7: Offset | R7: Function | S7: 2019 | Z7: {=IFERROR(_xlfn._xlws.FILTER(C7,E7="Tractor"),"")} -> Aboubacry Goby BASSOUM | AA7: Aboubacry Goby BASSOUM | AB7: {=IFERROR(_xlfn._xlws.FILTER(C7,F7="Combine Harvester"),"")} | AC7: Union Hydraulique de Kobilo | AE7: Samba KANE | AF7: =_xlfn.XLOOKUP(AE7,$C$3:$C$94,$D$3:$D$94,"") -> Private | AG7: Union Hydraulique de Kobilo | AH7: =_xlfn.XLOOKUP(AG7,$C$3:$C$94,$D$3:$D$94,"") -> Union
A8: 3 | B8: Matam | C8: Comité de Gestion de Woudourou 1 | D8: Private | E8: Tractor | G8: Nabadji Civol | H8: Nabadji | I8: Seydou Kane | J8: 77 617 00 25 77 555 77 98 | K8: VALTRA | N8: Moins de 100 | O8: Function | P8: 2015 | Q8: Offset | R8: Function | S8: 2015 | Z8: {=IFERROR(_xlfn._xlws.FILTER(C8,E8="Tractor"),"")} -> Comité de Gestion de Woudourou 1 | AA8: Comité de Gestion de Woudourou 1 | AB8: {=IFERROR(_xlfn._xlws.FILTER(C8,F8="Combine Harvester"),"")} | AC8: Union Hydraulique de Hamady Ounaré | AE8: Union Hydraulique de Dolol/Wodobéré | AF8: =_xlfn.XLOOKUP(AE8,$C$3:$C$94,$D$3:$D$94,"") -> Union | AG8: Union Régionale des Interprofessionnels de Semences (URIS) | AH8: =_xlfn.XLOOKUP(AG8,$C$3:$C$94,$D$3:$D$94,"") -> Private
A9: 4 | B9: Kanel | C9: Association des Agriculteurs de Waoundé | D9: Private | E9: Tractor | G9: Waoundé | H9: Orkadiere | I9: Samba Camara | J9: 77 562 49 16 | K9: John Deere | N9: 125 | O9: Function | P9: 2016 | Q9: Offset | R9: Function | S9: 2016 | Z9: {=IFERROR(_xlfn._xlws.FILTER(C9,E9="Tractor"),"")} -> Association des Agriculteurs de Waoundé | AA9: Association des Agriculteurs de Waoundé | AB9: {=IFERROR(_xlfn._xlws.FILTER(C9,F9="Combine Harvester"),"")} | AC9: Union Hydraulique de Ndouloumadji | AE9: Union Hydraulique de Hamady Ounaré | AF9: =_xlfn.XLOOKUP(AE9,$C$3:$C$94,$D$3:$D$94,"") -> Union | AG9: GIE Townde | AH9: =_xlfn.XLOOKUP(AG9,$C$3:$C$94,$D$3:$D$94,"") -> Private
A10: 4 | B10: Matam | C10: Déworoy Jokkéré Endam | D10: Private | E10: Tractor | G10: Nabadji Civol | H10: Nabadji | I10: Arona Sall | J10: 78 496 44 02 | K10: John Deere | N10: 125 | O10: Function | P10: 2016 | Q10: Offset | R10: Function | S10: 2016 | Z10: {=IFERROR(_xlfn._xlws.FILTER(C10,E10="Tractor"),"")} -> Déworoy Jokkéré Endam | AA10: Déworoy Jokkéré Endam | AB10: {=IFERROR(_xlfn._xlws.FILTER(C10,F10="Combine Harvester"),"")} | AC10: Union Régionale des Interprofessionnels de Semences (URIS) | AE10: Abdoulaye KANE | AF10: =_xlfn.XLOOKUP(AE10,$C$3:$C$94,$D$3:$D$94,"") -> Private | AG10: Union Hydraulique de Ndouloumadji | AH10: =_xlfn.XLOOKUP(AG10,$C$3:$C$94,$D$3:$D$94,"") -> Union
A11: 5 | B11: Kanel | C11: Bocar DAFF | D11: Private | E11: Tractor | G11: Ndendory | H11: Ndendory | I11: Bocar DAFF | J11: 775759153 | K11: TAFE | N11: 100 | O11: Function | P11: 2019 | Q11: Offset | R11: Function | S11: 2019 | Z11: {=IFERROR(_xlfn._xlws.FILTER(C11,E11="Tractor"),"")} -> Bocar DAFF | AA11: Bocar DAFF | AB11: {=IFERROR(_xlfn._xlws.FILTER(C11,F11="Combine Harvester"),"")} | AC11: Makhana Diéri | AE11: Diango DIABY | AF11: =_xlfn.XLOOKUP(AE11,$C$3:$C$94,$D$3:$D$94,"") -> Private
A12: 5 | B12: Matam | C12: Dieynaba Abdoul SY | D12: Private | E12: Tractor | G12: Agnam Civol | H12: Agnam/Oréfondé | I12: Dieynaba Abdoul SY | J12: 77120989 | K12: TAFE | N12: 100 | O12: Function | P12: 2019 | Q12: Offset | R12: Function | S12: 2019 | Z12: {=IFERROR(_xlfn._xlws.FILTER(C12,E12="Tractor"),"")} -> Dieynaba Abdoul SY | AA12: Dieynaba Abdoul SY | AB12: {=IFERROR(_xlfn._xlws.FILTER(C12,F12="Combine Harvester"),"")} | AE12: GIE Alla Lewy | AF12: =_xlfn.XLOOKUP(AE12,$C$3:$C$94,$D$3:$D$94,"") -> Private
A13: 6 | B13: Kanel | C13: Diango DIABY | D13: Private | E13: Tractor | G13: Hamady Ounaré | H13: Ndendory | I13: Diango DIABY | J13: 776574960 | K13: TAFE | N13: 100 | O13: Function | P13: 2019 | Q13: Offset | R13: Function | S13: 2019 | Z13: {=IFERROR(_xlfn._xlws.FILTER(C13,E13="Tractor"),"")} -> Diango DIABY | AA13: Diango DIABY | AB13: {=IFERROR(_xlfn._xlws.FILTER(C13,F13="Combine Harvester"),"")} | AE13: GIE Ngano | AF13: =_xlfn.XLOOKUP(AE13,$C$3:$C$94,$D$3:$D$94,"") -> Private
A14: 6 | B14: Matam | C14: GIE Alphala | D14: Private | E14: Tractor | G14: Nabadji Civol | H14: Nabadji | I14: Abdoulaye Gassama | J14: 77 966 50 84 | K14: John Deere | N14: 125 | O14: Function | P14: 2016 | Q14: Offset | R14: Function | S14: 2016 | Z14: {=IFERROR(_xlfn._xlws.FILTER(C14,E14="Tractor"),"")} -> GIE Alphala | AA14: GIE Alphala | AB14: {=IFERROR(_xlfn._xlws.FILTER(C14,F14="Combine Harvester"),"")} | AE14: Amadou KANE | AF14: =_xlfn.XLOOKUP(AE14,$C$3:$C$94,$D$3:$D$94,"") -> Private
A15: 7 | B15: Kanel | C15: GIE Alla Lewy | D15: Private | E15: Tractor | G15: Hamady Ounaré | H15: Ndendory | I15: Souleymane Diagana | J15: 77 671 02 95 | K15: VALTRA | N15: Moins de 100 | O15: Function | P15: 2015 | Q15: Offset | R15: Function | S15: 2015 | Z15: {=IFERROR(_xlfn._xlws.FILTER(C15,E15="Tractor"),"")} -> GIE Alla Lewy | AA15: GIE Alla Lewy | AB15: {=IFERROR(_xlfn._xlws.FILTER(C15,F15="Combine Harvester"),"")} | AE15: Bocar DAFF | AF15: =_xlfn.XLOOKUP(AE15,$C$3:$C$94,$D$3:$D$94,"") -> Private
A16: 7 | B16: Matam | C16: GIE Dowourou | D16: Private | E16: Tractor | G16: Agnam Civol | H16: Agnam/Oréfondé | I16: Abdou Aziz Diop | J16: 77 350 56 60 | K16: John Deere | N16: 125 | O16: Function | P16: 2016 | Q16: Offset | R16: Function | S16: 2016 | Z16: {=IFERROR(_xlfn._xlws.FILTER(C16,E16="Tractor"),"")} -> GIE Dowourou | AA16: GIE Dowourou | AB16: {=IFERROR(_xlfn._xlws.FILTER(C16,F16="Combine Harvester"),"")} | AE16: Thierno Hameth SALL | AF16: =_xlfn.XLOOKUP(AE16,$C$3:$C$94,$D$3:$D$94,"") -> Private
A17: 8 | B17: Kanel | C17: Union Hydraulique de Hamady Ounaré | D17: Union | E17: Tractor | G17: Hamady Ounaré | H17: Ndendory | I17: Abdoulaye KANE | J17: 77 632 39 35 | K17: CASE | O17: Function | P17: N/A | R17: N/A | Z17: {=IFERROR(_xlfn._xlws.FILTER(C17,E17="Tractor"),"")} -> Union Hydraulique de Hamady Ounaré | AA17: Union Hydraulique de Hamady Ounaré | AB17: {=IFERROR(_xlfn._xlws.FILTER(C17,F17="Combine Harvester"),"")} | AE17: Talla | AF17: =_xlfn.XLOOKUP(AE17,$C$3:$C$94,$D$3:$D$94,"") -> Private
A18: 8 | B18: Matam | C18: GIE Fadigada | D18: Private | E18: Tractor | G18: Dabia | H18: Dabia | I18: Mamadou Kane | J18: 77 563 64 97 | K18: John Deere | N18: 125 | O18: Function | P18: 2016 | Q18: Offset | R18: Function | S18: 2016 | Z18: {=IFERROR(_xlfn._xlws.FILTER(C18,E18="Tractor"),"")} -> GIE Fadigada | AA18: GIE Fadigada | AB18: {=IFERROR(_xlfn._xlws.FILTER(C18,F18="Combine Harvester"),"")} | AE18: Mamadou TALL | AF18: =_xlfn.XLOOKUP(AE18,$C$3:$C$94,$D$3:$D$94,"") -> Private
A19: 9 | B19: Kanel | C19: GIE Dagano | D19: Private | E19: Tractor | F19: Combine Harvester | G19: Orkadiéré | H19: Orkadiere | I19: Arona Dagano | J19: 77 693 06 56 | K19: John Deere | N19: 125 | O19: Breakdown | P19: 2008 | Q19: Offset | R19: Function | S19: 2008 | V19: Autre | W19: Breakdown | X19: 2019 | Z19: {=IFERROR(_xlfn._xlws.FILTER(C19,E19="Tractor"),"")} -> GIE Dagano | AA19: GIE Dagano | AB19: {=IFERROR(_xlfn._xlws.FILTER(C19,F19="Combine Harvester"),"")} -> GIE Dagano | AE19: Docteur DAFF | AF19: =_xlfn.XLOOKUP(AE19,$C$3:$C$94,$D$3:$D$94,"") -> Private
A20: 9 | B20: Matam | C20: GIE Moyyere Thierno Yaya | D20: Private | E20: Tractor | G20: Nabadji Civol | H20: Nabadji | I20: Oumar Deme | J20: 77 643 65 61 | K20: John Deere | N20: 125 | O20: Function | P20: 2016 | Q20: Offset | R20: Function | S20: 2016 | Z20: {=IFERROR(_xlfn._xlws.FILTER(C20,E20="Tractor"),"")} -> GIE Moyyere Thierno Yaya | AA20: GIE Moyyere Thierno Yaya | AB20: {=IFERROR(_xlfn._xlws.FILTER(C20,F20="Combine Harvester"),"")} | AE20: Moussa BEYTA | AF20: =_xlfn.XLOOKUP(AE20,$C$3:$C$94,$D$3:$D$94,"") -> Private
A21: 10 | B21: Kanel | C21: GIE Dagano | D21: Private | E21: Tractor | F21: Combine Harvester | G21: Orkadiéré | H21: Orkadiere | I21: Arona Dagano | J21: 78 693 06 56 | K21: John Deere | N21: 125 | O21: Breakdown | P21: 2009 | Q21: Offset | R21: Function | S21: 2009 | V21: Autre | W21: Breakdown | X21: 2019 | Z21: {=IFERROR(_xlfn._xlws.FILTER(C21,E21="Tractor"),"")} -> GIE Dagano | AA21: GIE Ndéma | AB21: {=IFERROR(_xlfn._xlws.FILTER(C21,F21="Combine Harvester"),"")} -> GIE Dagano | AE21: GIE Dembacané 2 | AF21: =_xlfn.XLOOKUP(AE21,$C$3:$C$94,$D$3:$D$94,"") -> Private
A22: 10 | B22: Matam | C22: GIE Ndéma | D22: Private | E22: Tractor | G22: Nabadji Civol | H22: Nabadji | I22: El Hadji Malick Dème | J22: 77 551 73 84 | K22: John Deere | N22: 125 | O22: Function | P22: 2016 | Q22: Offset | R22: Function | S22: 2016 | Z22: {=IFERROR(_xlfn._xlws.FILTER(C22,E22="Tractor"),"")} -> GIE Ndéma | AA22: GIE Raky Ganna | AB22: {=IFERROR(_xlfn._xlws.FILTER(C22,F22="Combine Harvester"),"")} | AE22: GIE Nourou Cheikh Moussa Camara | AF22: =_xlfn.XLOOKUP(AE22,$C$3:$C$94,$D$3:$D$94,"") -> Private
A23: 11 | B23: Kanel | C23: GIE Dagano | D23: Private | E23: Tractor | F23: Combine Harvester | G23: Orkadiéré | H23: Orkadiere | I23: Arona Dagano | J23: 79 693 06 56 | K23: John Deere | N23: 125 | O23: Breakdown | P23: 2008 | Q23: Offset | R23: Function | S23: 2008 | V23: Autre | W23: Breakdown | X23: 2019 | Z23: {=IFERROR(_xlfn._xlws.FILTER(C23,E23="Tractor"),"")} -> GIE Dagano | AA23: GIE Sognane et Frères | AB23: {=IFERROR(_xlfn._xlws.FILTER(C23,F23="Combine Harvester"),"")} -> GIE Dagano | AE23: GIE Dagano | AF23: =_xlfn.XLOOKUP(AE23,$C$3:$C$94,$D$3:$D$94,"") -> Private
A24: 11 | B24: Matam | C24: GIE Raky Ganna | D24: Private | E24: Tractor | G24: Matam | H24: Matam/ogo | I24: Abou Thioub | J24: 77 542 42 88 | K24: VALTRA | N24: Moins de 100 | O24: Function | P24: 2015 | Q24: Offset | R24: Function | S24: 2015 | Z24: {=IFERROR(_xlfn._xlws.FILTER(C24,E24="Tractor"),"")} -> GIE Raky Ganna | AA24: GIE Townde | AB24: {=IFERROR(_xlfn._xlws.FILTER(C24,F24="Combine Harvester"),"")} | AE24: GIE Ganguel | AF24: =_xlfn.XLOOKUP(AE24,$C$3:$C$94,$D$3:$D$94,"") -> Private
A25: 12 | B25: Kanel | C25: GIE Dagano | D25: Private | E25: Tractor | F25: Combine Harvester | G25: Orkadiéré | H25: Orkadiere | I25: Arona Dagano | J25: 80 693 06 56 | K25: John Deere | N25: 125 | O25: Breakdown | P25: 2010 | Q25: Offset | R25: Function | S25: 2010 | V25: Autre | W25: Breakdown | X25: 2019 | Z25: {=IFERROR(_xlfn._xlws.FILTER(C25,E25="Tractor"),"")} -> GIE Dagano | AA25: GIE Yarnde | AB25: {=IFERROR(_xlfn._xlws.FILTER(C25,F25="Combine Harvester"),"")} -> GIE Dagano | AE25: GIE Jokkéré Endam Wendou Bosséabé | AF25: =_xlfn.XLOOKUP(AE25,$C$3:$C$94,$D$3:$D$94,"") -> Private
A26: 12 | B26: Matam | C26: GIE Raky Ganna | D26: Private | E26: Tractor | G26: Matam | H26: Matam/ogo | I26: Abou Thioub | J26: 78 542 42 88 | K26: John Deere | N26: 125 | O26: Function | P26: 2016 | Q26: Offset | R26: Function | S26: 2016 | Z26: {=IFERROR(_xlfn._xlws.FILTER(C26,E26="Tractor"),"")} -> GIE Raky Ganna | AA26: Harouna DIOP | AB26: {=IFERROR(_xlfn._xlws.FILTER(C26,F26="Combine Harvester"),"")} | AE26: GIE PiP Balel | AF26: =_xlfn.XLOOKUP(AE26,$C$3:$C$94,$D$3:$D$94,"") -> Private
A27: 13 | B27: Kanel | C27: GIE Dagano | D27: Private | E27: Tractor | F27: Combine Harvester | G27: Orkadiéré | H27: Orkadiere | I27: Arona Dagano | J27: 81 693 06 56 | K27: John Deere | N27: 125 | O27: Breakdown | P27: 2008 | Q27: Offset | R27: Function | S27: 2008 | V27: Autre | W27: Breakdown | X27: 2019 | Z27: {=IFERROR(_xlfn._xlws.FILTER(C27,E27="Tractor"),"")} -> GIE Dagano | AA27: Mamadou BA | AB27: {=IFERROR(_xlfn._xlws.FILTER(C27,F27="Combine Harvester"),"")} -> GIE Dagano | AE27: Mbegnouga et frères | AF27: =_xlfn.XLOOKUP(AE27,$C$3:$C$94,$D$3:$D$94,"") -> Private
A28: 13 | B28: Matam | C28: GIE Sognane et Frères | D28: Private | E28: Tractor | G28: Nabadji Civol | H28: Nabadji | I28: Maissa Yero Sognane | J28: 77 609 42 72 | K28: John Deere | N28: 125 | O28: Function | P28: 2016 | Q28: Offset | R28: Function | S28: 2016 | Z28: {=IFERROR(_xlfn._xlws.FILTER(C28,E28="Tractor"),"")} -> GIE Sognane et Frères | AA28: GIE Dembacané 2 | AB28: {=IFERROR(_xlfn._xlws.FILTER(C28,F28="Combine Harvester"),"")} | AE28: Union Orkadiéré | AF28: =_xlfn.XLOOKUP(AE28,$C$3:$C$94,$D$3:$D$94,"") -> Union
A29: 14 | B29: Kanel | C29: GIE Dagano | D29: Private | E29: Tractor | F29: Combine Harvester | G29: Orkadiéré | H29: Orkadiere | I29: Arona Dagano | J29: 82 693 06 56 | K29: John Deere | N29: 125 | O29: Breakdown | P29: 2009 | Q29: Offset | R29: Function | S29: 2009 | V29: Autre | W29: Breakdown | X29: 2019 | Z29: {=IFERROR(_xlfn._xlws.FILTER(C29,E29="Tractor"),"")} -> GIE Dagano | AA29: Mamadou Lamine LY | AB29: {=IFERROR(_xlfn._xlws.FILTER(C29,F29="Combine Harvester"),"")} -> GIE Dagano | AE29: Famille Mbégnouga | AF29: =_xlfn.XLOOKUP(AE29,$C$3:$C$94,$D$3:$D$94,"") -> Private
A30: 14 | B30: Matam | C30: GIE Townde | D30: Private | E30: Tractor | F30: Combine Harvester | G30: Nabadji Civol | H30: Nabadji | I30: Sidy Dème | J30: 77 325 78 39 | K30: John Deere | N30: 125 | O30: Function | P30: 2016 | Q30: Offset | R30: Function | S30: 2016 | V30: Autre | W30: Function | X30: 2017 | Z30: {=IFERROR(_xlfn._xlws.FILTER(C30,E30="Tractor"),"")} -> GIE Townde | AA30: GIE Ganguel | AB30: {=IFERROR(_xlfn._xlws.FILTER(C30,F30="Combine Harvester"),"")} -> GIE Townde | AE30: Thierno Abdoul BA | AF30: =_xlfn.XLOOKUP(AE30,$C$3:$C$94,$D$3:$D$94,"") -> Private
A31: 15 | B31: Kanel | C31: GIE Dagano | D31: Private | E31: Tractor | F31: Combine Harvester | G31: Orkadiéré | H31: Orkadiere | I31: Arona Dagano | J31: 83 693 06 56 | K31: John Deere | N31: Moins de 100 | O31: Function | P31: 2010 | Q31: Offset | R31: Function | S31: 2010 | V31: Autre | W31: Function | X31: 2019 | Z31: {=IFERROR(_xlfn._xlws.FILTER(C31,E31="Tractor"),"")} -> GIE Dagano | AA31: Union Bosséa 1 | AB31: {=IFERROR(_xlfn._xlws.FILTER(C31,F31="Combine Harvester"),"")} -> GIE Dagano | AE31: Samba DIENG | AF31: =_xlfn.XLOOKUP(AE31,$C$3:$C$94,$D$3:$D$94,"") -> Private
A32: 15 | B32: Matam | C32: GIE Townde | D32: Private | E32: Tractor | G32: Nabadji Civol | H32: Nabadji | I32: Sidy Dème | J32: 78 325 78 39 | K32: TAFE | N32: 115 | O32: Function | P32: 2017 | Q32: Offset | R32: Function | S32: 2017 | Z32: {=IFERROR(_xlfn._xlws.FILTER(C32,E32="Tractor"),"")} -> GIE Townde | AA32: GIE Jokkéré Endam Wendou Bosséabé | AB32: {=IFERROR(_xlfn._xlws.FILTER(C32,F32="Combine Harvester"),"")} | AE32: Association des Agriculteurs de Waoundé | AF32: =_xlfn.XLOOKUP(AE32,$C$3:$C$94,$D$3:$D$94,"") -> Private
A33: 16 | B33: Kanel | C33: GIE Dagano | D33: Private | E33: Tractor | F33: Combine Harvester | G33: Orkadiéré | H33: Orkadiere | I33: Arona Dagano | J33: 84 693 06 56 | K33: John Deere | N33: Moins de 100 | O33: Function | P33: 2010 | Q33: Offset | R33: Function | S33: 2010 | V33: Autre | W33: Function | X33: 2019 | Z33: {=IFERROR(_xlfn._xlws.FILTER(C33,E33="Tractor"),"")} -> GIE Dagano | AA33: Mouhamadou Malick SALL | AB33: {=IFERROR(_xlfn._xlws.FILTER(C33,F33="Combine Harvester"),"")} -> GIE Dagano | AE33: GIE Waoundé 1 | AF33: =_xlfn.XLOOKUP(AE33,$C$3:$C$94,$D$3:$D$94,"") -> Private
A34: 16 | B34: Matam | C34: GIE Yarnde | D34: Private | E34: Tractor | G34: Bokidiawé | H34: Bokidiawé | I34: Bokar KANE | J34: 77 563 34 21 | K34: John Deere | N34: 125 | O34: Function | P34: 2016 | Q34: Offset | R34: Function | S34: 2016 | Z34: {=IFERROR(_xlfn._xlws.FILTER(C34,E34="Tractor"),"")} -> GIE Yarnde | AA34: GIE Ngano | AB34: {=IFERROR(_xlfn._xlws.FILTER(C34,F34="Combine Harvester"),"")} | AE34: BARRO | AF34: =_xlfn.XLOOKUP(AE34,$C$3:$C$94,$D$3:$D$94,"") -> Private
A35: 17 | B35: Kanel | C35: GIE Dagano | D35: Private | E35: Tractor | F35: Combine Harvester | G35: Orkadiéré | H35: Orkadiere | I35: Arona Dagano | J35: 85 693 06 56 | K35: John Deere | N35: 125 | O35: Function | P35: 2010 | Q35: Offset | R35: Function | S35: 2010 | V35: Autre | W35: Breakdown | X35: 2019 | Z35: {=IFERROR(_xlfn._xlws.FILTER(C35,E35="Tractor"),"")} -> GIE Dagano | AA35: Thierno Aliou Thiam | AB35: {=IFERROR(_xlfn._xlws.FILTER(C35,F35="Combine Harvester"),"")} -> GIE Dagano | AE35: Mamel DEME | AF35: =_xlfn.XLOOKUP(AE35,$C$3:$C$94,$D$3:$D$94,"") -> Private
A36: 17 | B36: Matam | C36: Harouna DIOP | D36: Union | E36: Tractor | G36: Nabadji Civol | H36: Nabadji | I36: Harouna DIOP | J36: 775566197 | K36: TAFE | N36: 100 | O36: Function | P36: 2019 | Q36: Offset | R36: Function | S36: 2019 | Z36: {=IFERROR(_xlfn._xlws.FILTER(C36,E36="Tractor"),"")} -> Harouna DIOP | AA36: GIE Nourou Cheikh Moussa Camara | AB36: {=IFERROR(_xlfn._xlws.FILTER(C36,F36="Combine Harvester"),"")} | AE36: Kisma Delba SOW | AF36: =_xlfn.XLOOKUP(AE36,$C$3:$C$94,$D$3:$D$94,"") -> Private
A37: 18 | B37: Kanel | C37: GIE Dagano | D37: Private | E37: Tractor | F37: Combine Harvester | G37: Orkadiéré | H37: Orkadiere | I37: Arona Dagano | J37: 86 693 06 56 | K37: John Deere | N37: 125 | O37: Function | P37: 2010 | Q37: Offset | R37: Function | S37: 2010 | V37: Autre | W37: Breakdown | X37: 2019 | Z37: {=IFERROR(_xlfn._xlws.FILTER(C37,E37="Tractor"),"")} -> GIE Dagano | AA37: Union Hydraulique de Matam | AB37: {=IFERROR(_xlfn._xlws.FILTER(C37,F37="Combine Harvester"),"")} -> GIE Dagano | AE37: Aboubacry Goby BASSOUM | AF37: =_xlfn.XLOOKUP(AE37,$C$3:$C$94,$D$3:$D$94,"") -> Private
A38: 18 | B38: Matam | C38: Mamadou BA | D38: Private | E38: Tractor | G38: Danthiady | H38: Matam/ogo | I38: Mamadou BA | J38: 776545626 | K38: TAFE | N38: 100 | O38: Function | P38: 2019 | Q38: Offset | R38: Function | S38: 2019 | Z38: {=IFERROR(_xlfn._xlws.FILTER(C38,E38="Tractor"),"")} -> Mamadou BA | AA38: GIE PiP Balel | AB38: {=IFERROR(_xlfn._xlws.FILTER(C38,F38="Combine Harvester"),"")} | AE38: Kadiatou BASSOUM | AF38: =_xlfn.XLOOKUP(AE38,$C$3:$C$94,$D$3:$D$94,"") -> Private
A39: 19 | B39: Kanel | C39: GIE Dembacané 2 | D39: Private | E39: Tractor | G39: Dembacané | H39: Orkadiere | I39: Baye Soumare | J39: 772769932 | K39: VALTRA | N39: Moins de 100 | O39: Function | P39: 2015 | Q39: Offset | R39: Function | S39: 2015 | Z39: {=IFERROR(_xlfn._xlws.FILTER(C39,E39="Tractor"),"")} -> GIE Dembacané 2 | AA39: GIE Waoundé 1 | AB39: {=IFERROR(_xlfn._xlws.FILTER(C39,F39="Combine Harvester"),"")} | AE39: Mamadou Abdoulaye MEYTY | AF39: =_xlfn.XLOOKUP(AE39,$C$3:$C$94,$D$3:$D$94,"") -> Private
A40: 19 | B40: Matam | C40: Mamadou Lamine LY | D40: Private | E40: Tractor | G40: Bokidiawé | H40: Bokidiawé | I40: Mamadou Lamine LY | J40: 776086580 | K40: TAFE | N40: 100 | O40: Function | P40: 2019 | Q40: Offset | R40: Function | S40: 2019 | Z40: {=IFERROR(_xlfn._xlws.FILTER(C40,E40="Tractor"),"")} -> Mamadou Lamine LY | AA40: Union de Sadel | AB40: {=IFERROR(_xlfn._xlws.FILTER(C40,F40="Combine Harvester"),"")} | AE40: Abou DIAW | AF40: =_xlfn.XLOOKUP(AE40,$C$3:$C$94,$D$3:$D$94,"") -> Private
...

Sheet Analysis
A1: Inventory Result (Matam and Kanel)
A3: Type of Machine
A4: Type of Machine | D4: Number of Machine
A5: Tractor | D5: =COUNTIF('Raw Data'!$E$3:$E$94,Analysis!A5) -> 92 | J5: =COUNTIFS('Raw Data'!$E$3:$E$94,Analysis!A5,'Raw Data'!$B$3:$B$94,"Matam") -> 40 | K5: =COUNTIFS('Raw Data'!$E$3:$E$94,Analysis!A5,'Raw Data'!$B$3:$B$94,"Kanel") -> 52
A6: Combine Harvester | D6: =COUNTIF('Raw Data'!$F$3:$F$94,Analysis!A6) -> 18 | J6: =COUNTIFS('Raw Data'!$F$3:$F$94,Analysis!A6,'Raw Data'!$B$3:$B$94,"Matam") -> 7 | K6: =COUNTIFS('Raw Data'!$F$3:$F$94,Analysis!A6,'Raw Data'!$B$3:$B$94,"Kanel") -> 11
A7: Total | D7: =SUM(D5:D6) -> 110
A9: Type of Owner
A10: Type of Owner | D10: Type of Machine | F10: Number of Owner | G10: Possetion Rate of Owner
A11: Union | D11: Tractor | F11: =COUNTIFS('Raw Data'!$D$3:$D$94,Analysis!A11,'Raw Data'!$E$3:$E$94,Analysis!D11) -> 19 | G11: =ROUND(F11/$D$5,2) -> 0.21
A12: Union | D12: Combine Harvester | F12: =COUNTIFS('Raw Data'!$D$3:$D$94,Analysis!A12,'Raw Data'!$F$3:$F$94,Analysis!D12) -> 5 | G12: =ROUND(F12/$D$6,2) -> 0.28
A13: Sub-total | F13: =SUM(F11:F12) -> 24 | G13: -
A14: Private | D14: Tractor | F14: =COUNTIFS('Raw Data'!$D$3:$D$94,Analysis!A14,'Raw Data'!$E$3:$E$94,Analysis!D14) -> 73 | G14: =ROUND(F14/$D$5,2) -> 0.79
A15: Private | D15: Combine Harvester | F15: =COUNTIFS('Raw Data'!$D$3:$D$94,Analysis!A15,'Raw Data'!$F$3:$F$94,Analysis!D15) -> 13 | G15: =ROUND(F15/$D$6,2) -> 0.72
A16: Sub-total | F16: =SUM(F14:F15) -> 86 | G16: -
A17: Total | F17: =SUMIF(A11:A16,"Sub-total",F11:F16) -> 110 | G17: -
A19: Operational Situation of Machine
A20: Operation Situation | D20: Type of Machine | F20: Number of Operational Machine | G20: Operational Rate
A21: Function | D21: Tractor | F21: =COUNTIFS('Raw Data'!$O$3:$O$94,Analysis!A21,'Raw Data'!$E$3:$E$94,Analysis!D21) -> 73 | G21: =ROUND(F21/$D$5,2) -> 0.79 | J21: =COUNTIFS('Raw Data'!$O$3:$O$94,Analysis!A21,'Raw Data'!$E$3:$E$94,Analysis!D21,'Raw Data'!$B$3:$B$94,"Matam") -> 37 | K21: =COUNTIFS('Raw Data'!$O$3:$O$94,Analysis!A21,'Raw Data'!$E$3:$E$94,Analysis!D21,'Raw Data'!$B$3:$B$94,"Kanel") -> 36
A22: Function | D22: Combine Harvester | F22: =COUNTIFS('Raw Data'!$W$3:$W$94,Analysis!A22,'Raw Data'!$F$3:$F$94,Analysis!D22) -> 9 | G22: =ROUND(F22/$D$6,2) -> 0.5 | J22: =COUNTIFS('Raw Data'!$W$3:$W$94,Analysis!A22,'Raw Data'!$F$3:$F$94,Analysis!D22,'Raw Data'!$B$3:$B$94,"Matam") -> 6 | K22: =COUNTIFS('Raw Data'!$W$3:$W$94,Analysis!A22,'Raw Data'!$F$3:$F$94,Analysis!D22,'Raw Data'!$B$3:$B$94,"Kanel") -> 3
A23: Sub-total | F23: =SUM(F21:F22) -> 82 | G23: -
A24: Breakdown | D24: Tractor | F24: =COUNTIFS('Raw Data'!$O$3:$O$94,Analysis!A24,'Raw Data'!$E$3:$E$94,Analysis!D24) -> 14 | G24: =ROUND(F24/$D$5,2) -> 0.15
A25: Breakdown | D25: Combine Harvester | F25: =COUNTIFS('Raw Data'!$W$3:$W$94,Analysis!A25,'Raw Data'!$F$3:$F$94,Analysis!D25) -> 9 | G25: =ROUND(F25/$D$6,2) -> 0.5
A26: Sub-total | F26: =SUM(F24:F25) -> 23 | G26: -
A27: N/A | D27: Tractor | F27: =COUNTIFS('Raw Data'!$O$3:$O$94,Analysis!A27,'Raw Data'!$E$3:$E$94,Analysis!D27) -> 5 | G27: =ROUND(F27/$D$5,2) -> 0.05
A28: N/A | D28: Combine Harvester | F28: =COUNTIFS('Raw Data'!$W$3:$W$94,Analysis!A28,'Raw Data'!$F$3:$F$94,Analysis!D28) -> 0 | G28: =ROUND(F28/$D$6,2) -> 0
A29: Sub-total | F29: =SUM(F27:F28) -> 5 | G29: -
A30: Total | F30: =SUMIF(A21:A29,"Sub-total",F21:F29) -> 110
A32: Owner-basis Operational Situation of Tractor
A33: Type of Owner | D33: Operation Situation | E33: Type of Machine | F33: Number of Operational Machine | G33: Operational Rate
A34: Union | D34: Function | E34: Tractor | F34: =COUNTIFS('Raw Data'!$D$3:$D$94,Analysis!A34,'Raw Data'!$O$3:$O$94,Analysis!D34,'Raw Data'!$E$3:$E$94,E34) -> 13 | G34: =ROUND(F34/$F$36,2) -> 0.72
A35: Union | D35: Breakdown | E35: Tractor | F35: =COUNTIFS('Raw Data'!$D$3:$D$94,Analysis!A35,'Raw Data'!$O$3:$O$94,Analysis!D35,'Raw Data'!$E$3:$E$94,E35) -> 5 | G35: =ROUND(F35/$F$36,2) -> 0.28
A36: Sub-total | F36: =SUM(F34:F35) -> 18 | G36: -
A37: Private | D37: Function | E37: Tractor | F37: =COUNTIFS('Raw Data'!$D$3:$D$94,Analysis!A37,'Raw Data'!$O$3:$O$94,Analysis!D37,'Raw Data'!$E$3:$E$94,E37) -> 60 | G37: =ROUND(F37/$F$39,2) -> 0.87
A38: Private | D38: Breakdown | E38: Tractor | F38: =COUNTIFS('Raw Data'!$D$3:$D$94,Analysis!A38,'Raw Data'!$O$3:$O$94,Analysis!D38,'Raw Data'!$E$3:$E$94,E38) -> 9 | G38: =ROUND(F38/$F$39,2) -> 0.13
A39: Sub-total | F39: =SUM(F37:F38) -> 69 | G39: -
A41: Owner-basis Operational Situation of Combine Harvester
A42: Type of Owner | D42: Operation Situation | E42: Type of Machine | F42: Number of Operational Machine | G42: Operational Rate
A43: Union | D43: Function | E43: Combine Harvester | F43: =COUNTIFS('Raw Data'!$D$3:$D$94,Analysis!A43,'Raw Data'!$W$3:$W$94,Analysis!D43,'Raw Data'!$F$3:$F$94,E43) -> 5 | G43: =ROUND(F43/$F$45,2) -> 1
A44: Union | D44: Breakdown | E44: Combine Harvester | F44: =COUNTIFS('Raw Data'!$D$3:$D$94,Analysis!A44,'Raw Data'!$W$3:$W$94,Analysis!D44,'Raw Data'!$F$3:$F$94,E44) -> 0 | G44: =ROUND(F44/$F$45,2) -> 0
A45: Sub-total | F45: =SUM(F43:F44) -> 5 | G45: -
...

Sheet Analysis_Commune
A1: Nombre de tracteurs
A2: Secteur | B2: Commune | C2: Type materiel | D2: Type materiel | E2: Nombre de tracteurs
E3: Bon état | F3: Panne
E4: Function | F4: Breakdown
A5: Agnam/Oréfondé | B5: Agnam Civol | C5: Tracteur | D5: Tractor | E5: =COUNTIFS('Raw Data'!$G$3:$G$94,Analysis_Commune!$B5,'Raw Data'!$E$3:$E$94,Analysis_Commune!$D5,'Raw Data'!$O$3:$O$94,Analysis_Commune!E$4) -> 2 | F5: =COUNTIFS('Raw Data'!$G$3:$G$94,Analysis_Commune!$B5,'Raw Data'!$E$3:$E$94,Analysis_Commune!$D5,'Raw Data'!$O$3:$O$94,Analysis_Commune!F$4) -> 0
A6: Sous-total | E6: =SUM(E5) -> 2 | F6: =SUM(F5) -> 0
A7: Bokidiawé | B7: Bokidiawé | C7: Tracteur | D7: Tractor | E7: =COUNTIFS('Raw Data'!$G$3:$G$94,Analysis_Commune!$B7,'Raw Data'!$E$3:$E$94,Analysis_Commune!$D7,'Raw Data'!$O$3:$O$94,Analysis_Commune!E$4) -> 10 | F7: =COUNTIFS('Raw Data'!$G$3:$G$94,Analysis_Commune!$B7,'Raw Data'!$E$3:$E$94,Analysis_Commune!$D7,'Raw Data'!$O$3:$O$94,Analysis_Commune!F$4) -> 0
A8: Sous-total | E8: =SUM(E7:E7) -> 10 | F8: =SUM(F7:F7) -> 0
A9: Dabia | B9: Dabia | C9: Tracteur | D9: Tractor | E9: =COUNTIFS('Raw Data'!$G$3:$G$94,Analysis_Commune!$B9,'Raw Data'!$E$3:$E$94,Analysis_Commune!$D9,'Raw Data'!$O$3:$O$94,Analysis_Commune!E$4) -> 5 | F9: =COUNTIFS('Raw Data'!$G$3:$G$94,Analysis_Commune!$B9,'Raw Data'!$E$3:$E$94,Analysis_Commune!$D9,'Raw Data'!$O$3:$O$94,Analysis_Commune!F$4) -> 0
A10: Sous-total | E10: =SUM(E9:E9) -> 5 | F10: =SUM(F9:F9) -> 0
A11: Matam/ogo | B11: Danthiady | C11: Tracteur | D11: Tractor | E11: =COUNTIFS('Raw Data'!$G$3:$G$94,Analysis_Commune!$B11,'Raw Data'!$E$3:$E$94,Analysis_Commune!$D11,'Raw Data'!$O$3:$O$94,Analysis_Commune!E$4) -> 1 | F11: =COUNTIFS('Raw Data'!$G$3:$G$94,Analysis_Commune!$B11,'Raw Data'!$E$3:$E$94,Analysis_Commune!$D11,'Raw Data'!$O$3:$O$94,Analysis_Commune!F$4) -> 0
A12: Matam/ogo | B12: Matam | C12: Tracteur | D12: Tractor | E12: =COUNTIFS('Raw Data'!$G$3:$G$94,Analysis_Commune!$B12,'Raw Data'!$E$3:$E$94,Analysis_Commune!$D12,'Raw Data'!$O$3:$O$94,Analysis_Commune!E$4) -> 3 | F12: =COUNTIFS('Raw Data'!$G$3:$G$94,Analysis_Commune!$B12,'Raw Data'!$E$3:$E$94,Analysis_Commune!$D12,'Raw Data'!$O$3:$O$94,Analysis_Commune!F$4) -> 2
A13: Matam/ogo | B13: Ogo | C13: Tracteur | D13: Tractor | E13: =COUNTIFS('Raw Data'!$G$3:$G$94,Analysis_Commune!$B13,'Raw Data'!$E$3:$E$94,Analysis_Commune!$D13,'Raw Data'!$O$3:$O$94,Analysis_Commune!E$4) -> 1 | F13: =COUNTIFS('Raw Data'!$G$3:$G$94,Analysis_Commune!$B13,'Raw Data'!$E$3:$E$94,Analysis_Commune!$D13,'Raw Data'!$O$3:$O$94,Analysis_Commune!F$4) -> 0
A14: Matam/ogo | B14: Ourossogui | C14: Tracteur | D14: Tractor | E14: =COUNTIFS('Raw Data'!$G$3:$G$94,Analysis_Commune!$B14,'Raw Data'!$E$3:$E$94,Analysis_Commune!$D14,'Raw Data'!$O$3:$O$94,Analysis_Commune!E$4) -> 3 | F14: =COUNTIFS('Raw Data'!$G$3:$G$94,Analysis_Commune!$B14,'Raw Data'!$E$3:$E$94,Analysis_Commune!$D14,'Raw Data'!$O$3:$O$94,Analysis_Commune!F$4) -> 0
A15: Sous-total | E15: =SUM(E11:E14) -> 8 | F15: =SUM(F11:F14) -> 2
A16: Nabadji | B16: Nabadji Civol | C16: Tracteur | D16: Tractor | E16: =COUNTIFS('Raw Data'!$G$3:$G$94,Analysis_Commune!$B16,'Raw Data'!$E$3:$E$94,Analysis_Commune!$D16,'Raw Data'!$O$3:$O$94,Analysis_Commune!E$4) -> 12 | F16: =COUNTIFS('Raw Data'!$G$3:$G$94,Analysis_Commune!$B16,'Raw Data'!$E$3:$E$94,Analysis_Commune!$D16,'Raw Data'!$O$3:$O$94,Analysis_Commune!F$4) -> 0
A17: Sous-total | E17: =SUM(E16) -> 12 | F17: =SUM(F16) -> 0
A18: Aouré | B18: Aouré | C18: Tracteur | D18: Tractor | E18: =COUNTIFS('Raw Data'!$G$3:$G$94,Analysis_Commune!$B18,'Raw Data'!$E$3:$E$94,Analysis_Commune!$D18,'Raw Data'!$O$3:$O$94,Analysis_Commune!E$4) -> 0 | F18: =COUNTIFS('Raw Data'!$G$3:$G$94,Analysis_Commune!$B18,'Raw Data'!$E$3:$E$94,Analysis_Commune!$D18,'Raw Data'!$O$3:$O$94,Analysis_Commune!F$4) -> 1
A19: Aouré | B19: Semmé | C19: Tracteur | D19: Tractor | E19: =COUNTIFS('Raw Data'!$G$3:$G$94,Analysis_Commune!$B19,'Raw Data'!$E$3:$E$94,Analysis_Commune!$D19,'Raw Data'!$O$3:$O$94,Analysis_Commune!E$4) -> 1 | F19: =COUNTIFS('Raw Data'!$G$3:$G$94,Analysis_Commune!$B19,'Raw Data'!$E$3:$E$94,Analysis_Commune!$D19,'Raw Data'!$O$3:$O$94,Analysis_Commune!F$4) -> 0
A20: Sous-total | E20: =SUM(E18:E19) -> 1 | F20: =SUM(F18:F19) -> 1
A21: Ndendory | B21: Hamady Ounaré | C21: Tracteur | D21: Tractor | E21: =COUNTIFS('Raw Data'!$G$3:$G$94,Analysis_Commune!$B21,'Raw Data'!$E$3:$E$94,Analysis_Commune!$D21,'Raw Data'!$O$3:$O$94,Analysis_Commune!E$4) -> 6 | F21: =COUNTIFS('Raw Data'!$G$3:$G$94,Analysis_Commune!$B21,'Raw Data'!$E$3:$E$94,Analysis_Commune!$D21,'Raw Data'!$O$3:$O$94,Analysis_Commune!F$4) -> 1
A22: Ndendory | B22: Ndendory | C22: Tracteur | D22: Tractor | E22: =COUNTIFS('Raw Data'!$G$3:$G$94,Analysis_Commune!$B22,'Raw Data'!$E$3:$E$94,Analysis_Commune!$D22,'Raw Data'!$O$3:$O$94,Analysis_Commune!E$4) -> 3 | F22: =COUNTIFS('Raw Data'!$G$3:$G$94,Analysis_Commune!$B22,'Raw Data'!$E$3:$E$94,Analysis_Commune!$D22,'Raw Data'!$O$3:$O$94,Analysis_Commune!F$4) -> 1
A23: Ndendory | B23: Sinthiou Bamambé | C23: Tracteur | D23: Tractor | E23: =COUNTIFS('Raw Data'!$G$3:$G$94,Analysis_Commune!$B23,'Raw Data'!$E$3:$E$94,Analysis_Commune!$D23,'Raw Data'!$O$3:$O$94,Analysis_Commune!E$4) -> 3 | F23: =COUNTIFS('Raw Data'!$G$3:$G$94,Analysis_Commune!$B23,'Raw Data'!$E$3:$E$94,Analysis_Commune!$D23,'Raw Data'!$O$3:$O$94,Analysis_Commune!F$4) -> 1
A24: Ndendory | B24: Wendou nody | C24: Tracteur | D24: Tractor | E24: =COUNTIFS('Raw Data'!$G$3:$G$94,Analysis_Commune!$B24,'Raw Data'!$E$3:$E$94,Analysis_Commune!$D24,'Raw Data'!$O$3:$O$94,Analysis_Commune!E$4) -> 1 | F24: =COUNTIFS('Raw Data'!$G$3:$G$94,Analysis_Commune!$B24,'Raw Data'!$E$3:$E$94,Analysis_Commune!$D24,'Raw Data'!$O$3:$O$94,Analysis_Commune!F$4) -> 0
A25: Sous-total | E25: =SUM(E21:E24) -> 13 | F25: =SUM(F21:F24) -> 3
A26: Orkadiéré | B26: Dembacané | C26: Tracteur | D26: Tractor | E26: =COUNTIFS('Raw Data'!$G$3:$G$94,Analysis_Commune!$B26,'Raw Data'!$E$3:$E$94,Analysis_Commune!$D26,'Raw Data'!$O$3:$O$94,Analysis_Commune!E$4) -> 1 | F26: =COUNTIFS('Raw Data'!$G$3:$G$94,Analysis_Commune!$B26,'Raw Data'!$E$3:$E$94,Analysis_Commune!$D26,'Raw Data'!$O$3:$O$94,Analysis_Commune!F$4) -> 0
A27: Orkadiéré | B27: Orkadiéré | C27: Tracteur | D27: Tractor | E27: =COUNTIFS('Raw Data'!$G$3:$G$94,Analysis_Commune!$B27,'Raw Data'!$E$3:$E$94,Analysis_Commune!$D27,'Raw Data'!$O$3:$O$94,Analysis_Commune!E$4) -> 12 | F27: =COUNTIFS('Raw Data'!$G$3:$G$94,Analysis_Commune!$B27,'Raw Data'!$E$3:$E$94,Analysis_Commune!$D27,'Raw Data'!$O$3:$O$94,Analysis_Commune!F$4) -> 7
A28: Orkadiéré | B28: Walel | C28: Tracteur | D28: Tractor | E28: =COUNTIFS('Raw Data'!$G$3:$G$94,Analysis_Commune!$B28,'Raw Data'!$E$3:$E$94,Analysis_Commune!$D28,'Raw Data'!$O$3:$O$94,Analysis_Commune!E$4) -> 1 | F28: =COUNTIFS('Raw Data'!$G$3:$G$94,Analysis_Commune!$B28,'Raw Data'!$E$3:$E$94,Analysis_Commune!$D28,'Raw Data'!$O$3:$O$94,Analysis_Commune!F$4) -> 0
A29: Orkadiéré | B29: Waoundé | C29: Tracteur | D29: Tractor | E29: =COUNTIFS('Raw Data'!$G$3:$G$94,Analysis_Commune!$B29,'Raw Data'!$E$3:$E$94,Analysis_Commune!$D29,'Raw Data'!$O$3:$O$94,Analysis_Commune!E$4) -> 2 | F29: =COUNTIFS('Raw Data'!$G$3:$G$94,Analysis_Commune!$B29,'Raw Data'!$E$3:$E$94,Analysis_Commune!$D29,'Raw Data'!$O$3:$O$94,Analysis_Commune!F$4) -> 0
A30: Sous-total | E30: =SUM(E26:E29) -> 16 | F30: =SUM(F26:F29) -> 7
A31: Semmé | B31: Dialloubé | C31: Tracteur | D31: Tractor | E31: =COUNTIFS('Raw Data'!$G$3:$G$94,Analysis_Commune!$B31,'Raw Data'!$E$3:$E$94,Analysis_Commune!$D31,'Raw Data'!$O$3:$O$94,Analysis_Commune!E$4) -> 1 | F31: =COUNTIFS('Raw Data'!$G$3:$G$94,Analysis_Commune!$B31,'Raw Data'!$E$3:$E$94,Analysis_Commune!$D31,'Raw Data'!$O$3:$O$94,Analysis_Commune!F$4) -> 0
A32: Semmé | B32: Doundé | C32: Tracteur | D32: Tractor | E32: =COUNTIFS('Raw Data'!$G$3:$G$94,Analysis_Commune!$B32,'Raw Data'!$E$3:$E$94,Analysis_Commune!$D32,'Raw Data'!$O$3:$O$94,Analysis_Commune!E$4) -> 0 | F32: =COUNTIFS('Raw Data'!$G$3:$G$94,Analysis_Commune!$B32,'Raw Data'!$E$3:$E$94,Analysis_Commune!$D32,'Raw Data'!$O$3:$O$94,Analysis_Commune!F$4) -> 0
A33: Sous-total | E33: =SUM(E31:E32) -> 1 | F33: =SUM(F31:F32) -> 0
A34: Wouro Sidy | B34: Kanel | C34: Tracteur | D34: Tractor | E34: =COUNTIFS('Raw Data'!$G$3:$G$94,Analysis_Commune!$B34,'Raw Data'!$E$3:$E$94,Analysis_Commune!$D34,'Raw Data'!$O$3:$O$94,Analysis_Commune!E$4) -> 3 | F34: =COUNTIFS('Raw Data'!$G$3:$G$94,Analysis_Commune!$B34,'Raw Data'!$E$3:$E$94,Analysis_Commune!$D34,'Raw Data'!$O$3:$O$94,Analysis_Commune!F$4) -> 1
A35: Wouro Sidy | B35: Ounaré | C35: Tracteur | D35: Tractor | E35: =COUNTIFS('Raw Data'!$G$3:$G$94,Analysis_Commune!$B35,'Raw Data'!$E$3:$E$94,Analysis_Commune!$D35,'Raw Data'!$O$3:$O$94,Analysis_Commune!E$4) -> 1 | F35: =COUNTIFS('Raw Data'!$G$3:$G$94,Analysis_Commune!$B35,'Raw Data'!$E$3:$E$94,Analysis_Commune!$D35,'Raw Data'!$O$3:$O$94,Analysis_Commune!F$4) -> 0
A36: Wouro Sidy | B36: Wouro Sidy | C36: Tracteur | D36: Tractor | E36: =COUNTIFS('Raw Data'!$G$3:$G$94,Analysis_Commune!$B36,'Raw Data'!$E$3:$E$94,Analysis_Commune!$D36,'Raw Data'!$O$3:$O$94,Analysis_Commune!E$4) -> 1 | F36: =COUNTIFS('Raw Data'!$G$3:$G$94,Analysis_Commune!$B36,'Raw Data'!$E$3:$E$94,Analysis_Commune!$D36,'Raw Data'!$O$3:$O$94,Analysis_Commune!F$4) -> 0
A37: Sous-total | E37: =SUM(E34:E36) -> 5 | F37: =SUM(F34:F36) -> 1
A38: Total | E38: =SUMIF($A5:$A37,"Sous-total",E5:E37) -> 73 | F38: =SUMIF($A5:$A37,"Sous-total",F5:F37) -> 14
A40: Nombre de moissonneuses-batteuses
A41: Secteur | B41: Commune | C41: Type materiel | D41: Type materiel | E41: Nombre de tracteurs
...
