Workbook

Sheet Thillé
A2: Delegation | B2: Secteur | C2: Caract materiels agricole | D2: type materiel | E2: Structure benef | F2: Type organisat | G2: Nom responsable | H2: Marque | I2: Modèle | J2: Numéro de série | K2: Telephone | L2: commune_zi | M2: Arrondissement | N2: Année acquisition | O2: Provenance | P2: Financement | Q2: Observations
A3: PODOR | B3: Thillé Boubacar | C3: Moissonneuse batteuse KARTAR pneu | D3: Moissonneuse Batteuse | E3: Boubacar Sall | F3: Individuel | G3: Boubacar Sall | H3: KARTAR | I3: SV Crop cruiser | K3: 77 659 75 68 | L3: NIANDANE | M3: Thillé Boubacar | N3: 2018 | O3: MAER | Q3: Panne
A4: PODOR | B4: Thillé Boubacar | C4: Moissonneuse batteuse VALTRA pneu | D4: Moissonneuse Batteuse | E4: Union Ngoro Fanaye SP1 | F4: Union | G4: Amadou Tall | H4: VALTRA | I4: BC 4600 | K4: 77 537 12 31 | L4: FANAYE | M4: Thillé Boubacar | N4: 2014 | O4: SAED | Q4: Panne
A5: PODOR | B5: Thillé Boubacar | C5: Moissonneuse batteuse VALTRA pneu | D5: Moissonneuse Batteuse | E5: Union Ngoro Fanaye SP1 | F5: Union | G5: Amadou Tall | H5: VALTRA | I5: BC 4500 | K5: 77 537 12 31 | L5: FANAYE | M5: Thillé Boubacar | N5: 2019 | O5: MAER | Q5: Bon état
A6: PODOR | B6: Thillé Boubacar | C6: Moissonneuse batteuse à chenille | D6: Moissonneuse Batteuse | E6: Union Ngoro Fanaye SP1 | F6: Union | G6: Amadou Tall | H6: SPEM | I6: DR50E22-1 | K6: 77 537 12 31 | L6: FANAYE | M6: Thillé Boubacar | N6: 2021 | O6: Coopération | Q6: Bon état
A7: PODOR | B7: Thillé Boubacar | C7: Moissonneuse batteuse Massey Fergusson pneu | D7: Moissonneuse Batteuse | E7: REFAN/PODOR | F7: Réseau | G7: Adama GAYE | H7: Massey Fergusson | I7: 32 Advanced | K7: 77 538 51 32 | L7: NIANDANE | M7: Thillé Boubacar | N7: 2019 | O7: MAER | Q7: Panne
A8: PODOR | B8: Thillé Boubacar | C8: TRACTEUR VALTRA DE 88 CV + PULVERISEUR OFFSET DE 20 DISQUES TRAINE | D8: Tracteur | E8: Union Cheikhou Oumar Loboudou Doué | F8: Union | G8: IBRAHIMA LY | H8: VALTRA | I8: BM125I | K8: 77 502 71 20 | L8: NDIAYENEPENDAO | M8: Thillé Boubacar | N8: 2014 | O8: SAED | Q8: Panne
A9: PODOR | B9: Thillé Boubacar | C9: Tracteur 132 CV + Offset 26 disques traine VALTRA | D9: Tracteur | E9: Union PIV ET PIP DE Fanaye | F9: Union | G9: ALHOUSSEYNOU DJIGO | H9: VALTRA | I9: A750L | K9: 77 563 93 32 | L9: FANAYE | M9: Thillé Boubacar | N9: 2014 | O9: SAED | Q9: Bon état
A10: PODOR | B10: Thillé Boubacar | C10: Tracteur 132 CV + Offset 26 disques traine VALTRA | D10: Tracteur | E10: FEGINA - NGALLENKA AMONT | F10: Union | G10: MOUSSA TALL | H10: VALTRA | I10: A750L | K10: 77 567 02 50 | L10: Ndiayenne Pendao | M10: Thillé Boubacar | N10: 2014 | O10: SAED | Q10: Panne | R10: Moeteur
A11: PODOR | B11: Thillé Boubacar | C11: TRACTEUR VALTRA DE 88 CV + PULVERISEUR OFFSET DE 20 DISQUES TRAINE | D11: Tracteur | E11: Union Thillé thiangaye | F11: Union | G11: Bocar KANE | H11: VALTRA | I11: A750L | K11: 77 561 27 03 | L11: NDIAYENEPENDAO | M11: Thillé Boubacar | N11: 2014 | O11: SAED | Q11: Moyen | R11: offset
A12: PODOR | B12: Thillé Boubacar | C12: TRACTEUR VALTRA DE 88 CV + PULVERISEUR OFFSET DE 20 DISQUES TRAINE | D12: Tracteur | E12: Dental MCA | F12: Union | G12: AMADOU MAHAM BA | H12: VALTRA | I12: A750L | K12: 77 898 17 06 | L12: NDIAYENEPENDAO | M12: Thillé Boubacar | N12: 2014 | O12: SAED | Q12: Moyen
A13: PODOR | B13: Thillé Boubacar | C13: Tracteur 125CV+Offset 28 disques Jonh deer | D13: Tracteur | E13: NDIEURBA SP2 | F13: Union | G13: MOUSTAPHA MBENGUE | H13: Jonh Deer | I13: 6125 | K13: 77 459 74 73 | L13: FANAYE | M13: Thillé Boubacar | N13: 2015 | O13: MAER | Q13: Bon état
A14: PODOR | B14: Thillé Boubacar | C14: Tracteur 125CV+Offset 28 disques Jonh deer | D14: Tracteur | E14: SP1 NGORO FANAYE | F14: Union | G14: AMADOU TALL | H14: Jonh Deer | I14: 6125 | K14: 77 537 12 31 | L14: FANAYE | M14: Thillé Boubacar | N14: 2015 | O14: MAER | Q14: Bon état
A15: PODOR | B15: Thillé Boubacar | C15: Tracteur 125CV+Offset 28 disques Jonh deer | D15: Tracteur | E15: UNION SUMA NIANGA | F15: Union | G15: DJIBO DIALLO | H15: Jonh Deer | I15: 6125 | K15: 77 561 74 69 | L15: NDIAYENEPENDAO | M15: Thillé Boubacar | N15: 2015 | O15: MAER | Q15: Bon état
A16: PODOR | B16: Thillé Boubacar | C16: tracteur 100 CV +Offset 24 disques TAFE | D16: Tracteur | E16: CODOU DIOP | F16: Individuel | G16: CODOU DIOP | H16: TAFE | I16: 1002 Heritage | K16: 77 265 32 30 | L16: FANAYE | M16: Thillé Boubacar | N16: 2018 | O16: MAER | Q16: Panne
A17: PODOR | B17: Thillé Boubacar | C17: tracteur 100 CV +Offset 24 disques TAFE | D17: Tracteur | E17: UNION DES GIE DE NGORO FANAYE | F17: Union | G17: Amadou TALL | H17: TAFE | I17: 1002 Heritage | K17: 77 537 12 31 | L17: FANAYE | M17: Thillé Boubacar | N17: 2018 | O17: MAER | Q17: Bon état
A18: PODOR | B18: Thillé Boubacar | C18: tracteur 100 CV +Offset 24 disques TAFE | D18: Tracteur | E18: UNION DES PIV DE NIANDANE | F18: Union | G18: Mamadou NIANE | H18: TAFE | I18: 1002 Heritage | K18: 77 518 20 27 | L18: NIANDANE | M18: Thillé Boubacar | N18: 2018 | O18: MAER | Q18: Bon état
A19: PODOR | B19: Thillé Boubacar | C19: tracteur 100 CV +Offset 24 disques TAFE | D19: Tracteur | E19: UNION THILLE - THIANGAYE | F19: Union | G19: Bocar KANE | H19: TAFE | I19: 1002 Heritage | K19: 77 561 27 03 | L19: NDIAYENEPENDAO | M19: Thillé Boubacar | N19: 2018 | O19: MAER | Q19: Bon état
A20: PODOR | B20: Thillé Boubacar | C20: tracteur 100 CV +Offset 24 disques TAFE | D20: Tracteur | E20: SERIGNE ABDOURAHMANE NIANE | F20: Individuel | G20: SERIGNE ABDOURAHMANE NIANE | H20: TAFE | I20: 1002 Heritage | K20: 77 564 33 17 | L20: NIANDANE | M20: Thillé Boubacar | N20: 2018 | O20: MAER | Q20: Bon état
A21: PODOR | B21: Thillé Boubacar | C21: tracteur 100 CV +Offset 24 disques TAFE | D21: Tracteur | E21: GIE FOUTA TORO | F21: Individuel | G21: THIERNO MADANI TALL | H21: TAFE | I21: 1002 Heritage | K21: 77 561 28 10 | L21: NDIAYENEPENDAO | M21: Thillé Boubacar | N21: 2018 | O21: MAER | Q21: Bon état
A22: PODOR | B22: Thillé Boubacar | C22: tracteur 100 CV +Offset 24 disques TAFE | D22: Tracteur | E22: ALIOU IBRAHIMA LY | F22: Individuel | G22: ALIOU IBRAHIMA LY | H22: TAFE | I22: 1002 Heritage | K22: 77 652 54 49 | L22: NDIAYENEPENDAO | M22: Thillé Boubacar | N22: 2018 | O22: MAER | Q22: Bon état
A23: PODOR | B23: Thillé Boubacar | C23: tracteur 100 CV +Offset 24 disques TAFE | D23: Tracteur | E23: GIE HAABADE BASSAL | F23: Individuel | G23: ALIOU KANE | H23: TAFE | I23: 1002 Heritage | K23: 77 652 49 50 | L23: NDIAYENEPENDAO | M23: Thillé Boubacar | N23: 2018 | O23: MAER | Q23: Bon état
A24: PODOR | B24: Thillé Boubacar | C24: Tracteur 125CV+Offset 28 disques Jonh deer | D24: Tracteur | E24: Union Dental MCA | F24: Union | G24: AMADOU MAHAM BA | H24: Jonh Deer | I24: 6125 | K24: 77 898 17 06 | L24: NDIAYENEPENDAO | M24: Thillé Boubacar | N24: 2016 | O24: MAER | Q24: Bon état
A25: PODOR | B25: Thillé Boubacar | C25: Tracteur 100CV+Offset 24 disques Dushter et remorque 10 T | D25: Tracteur | E25: Union des SUMAS de Nianga | F25: Union | G25: Djibo Diallo | H25: DEUTZ-FAHR | I25: 6130W Profi | K25: 77 561 74 69 | L25: Ndiayenne Pendao | M25: Thillé Boubacar | N25: 2024 | O25: MASAE | P25: LBA | Q25: Bon état | R25: avec offset
A26: PODOR | B26: Thillé Boubacar | C26: Moissonneuse batteuse à chenille FM WORLD | D26: Moissonneuse Batteuse | E26: Union des SUMAS de Nianga | F26: Union | G26: Djibo Diallo | H26: FM WORLD | I26: RUILONG | J26: 4LZ-4.0E | K26: 77 561 74 69 | L26: Ndiayenne Pendao | M26: Thillé Boubacar | N26: 2024 | O26: MASAE | P26: LBA | Q26: Bon état
A27: PODOR | B27: Thillé Boubacar | C27: Moissonneuse batteuse à chenille FM WORLD | D27: Moissonneuse Batteuse | E27: Union GIE pour le Développement Intégré de Niandane | F27: Union | G27: Mouhamadou Niane | H27: FM WORLD | I27: RUILONG | J27: 4LZ-4.0E | K27: 77 518 20 27 | L27: Niandane | M27: Thillé boubacar | N27: 2024 | O27: MASAE | P27: LBA | Q27: Bon état
A28: PODOR | B28: Thillé Boubacar | C28: Tracteur 100CV+Offset 24 disques Dushter et remorque 5 T | D28: Tracteur | E28: Interprofession des Producteurs d’oignon de Podor (IPOS) | F28: Faitière | G28: Boubacar Sall | H28: DEUTZ-FAHR | I28: 6130W Profi | K28: 77 659 75 68 | L28: Département de Podor | M28: Département | N28: 2024 | O28: MASAE | Q28: Notification
A29: PODOR | B29: Thillé Boubacar | C29: Moissonneuse batteuse à chenille FM WORLD | D29: Moissonneuse Batteuse | E29: Union des GIE de Ngoro Fanaye, | F29: Union | G29: Amadou Tall | H29: FM WORLD | I29: RUILONG | J29: 4LZ-4.0E | K29: 77 537 12 31 | L29: Fanaye | M29: Thillé boubacar | N29: 2024 | O29: MASAE | Q29: Notification
A30: PODOR | B30: Thillé Boubacar | C30: Tracteur 80CV+Offset 18 disques New Holland | D30: Tracteur | E30: Village de Diagnoum | F30: Village pilote | G30: Hamat Dia | H30: New Holland | I30: TD80D | K30: 77 720 93 62 | L30: Fanaye | M30: Thillé boubacar | N30: 2024 | O30: SAEMAUL | P30: Don | Q30: Bon état
A31: PODOR | B31: Thillé Boubacar | C31: Tracteur 80CV+Offset 18 disques New Holland | D31: Tracteur | E31: Village de Thillé Boubacar | F31: Village pilote | G31: Mamadou Diallo | H31: New Holland | I31: TD80D | K31: 70 406 91 40 | L31: Ndiayene Pendao | M31: Thillé boubacar | N31: 2024 | O31: SAEMAUL | P31: Don | Q31: Bon état
A32: PODOR | B32: Thillé Boubacar | C32: Moissonneuse batteuse à chenille Class | D32: Moissonneuse Batteuse | E32: COOP Toro KOICA | F32: Coopérative | G32: Amadou Sy | H32: Claas | I32: CROP TIGER 40 | K32: 76 600 66 63 | L32: Ndiayene Pendao / Guédé village | M32: Thillé boubacar/gamadji | N32: 2024 | O32: PDCVR2 | P32: DON | Q32: Bon état
A33: PODOR | B33: Thillé Boubacar | C33: Moissonneuse batteuse à chenille Class | D33: Moissonneuse Batteuse | E33: COOP Toro KOICA | F33: Coopérative | G33: Amadou Sy | H33: Claas | I33: CROP TIGER 40 | K33: 76 600 66 63 | L33: Ndiayene Pendao / Guédé village | M33: Thillé boubacar/gamadji | N33: 2024 | O33: PDCVR2 | P33: DON | Q33: Bon état
A34: PODOR | B34: Thillé Boubacar | C34: Moissonneuse batteuse à chenille Class | D34: Moissonneuse Batteuse | E34: COOP Toro KOICA | F34: Coopérative | G34: Amadou Sy | H34: Claas | I34: CROP TIGER 40 | K34: 76 600 66 63 | L34: Ndiayene Pendao / Guédé village | M34: Thillé boubacar/gamadji | N34: 2024 | O34: PDCVR2 | P34: DON | Q34: Bon état
A35: PODOR | B35: Thillé Boubacar | C35: Tracteur 125CV+Offset 24 disques New Holland | D35: Tracteur | E35: COOP Toro KOICA | F35: Coopérative | G35: Amadou Sy | H35: New Holland | I35: T6050 | K35: 76 600 66 63 | L35: Ndiayene Pendao | M35: Thillé boubacar | N35: 2024 | O35: PDCVR2 | P35: Don | Q35: Bon état
A36: PODOR | B36: Thillé Boubacar | C36: Tracteur 125CV+Offset 28 disques New Holland | D36: Tracteur | E36: Privé | F36: Privé | G36: Ibrahima Sall | H36: New Holland | I36: T6050 | K36: 77 643 91 55 | L36: Ndiayene Pendao | M36: Thillé boubacar | N36: 2024 | O36: Projet | P36: LBA | Q36: Bon état
A37: PODOR | B37: Thillé Boubacar | C37: Moissonneuse batteuse new holland pneu | D37: Moissonneuse Batteuse | E37: Privé | F37: Privé | G37: Ibrahima Sall | H37: New Holland | I37: TC5.30 | J37: 530 | K37: 77 643 91 55 | L37: Ndiayene Pendao | M37: Thillé boubacar | N37: 2024 | O37: Projet | P37: LBA | Q37: Bon état
A38: PODOR | B38: Thillé Boubacar | C38: Tracteur 125CV+Offset 28 disques New Holland | D38: Tracteur | E38: Privé | F38: Privé | G38: Hamath Guèye | H38: New Holland | I38: T6050 | K38: 77 658 72 88 | L38: Ndiayene Pendao | M38: Thillé boubacar | N38: 2016 | O38: MAER | P38: LBA | Q38: Bon état

Sheet Gamadji
A2: Delegation | B2: Secteur | C2: Caract materiels agricole | D2: type materiel | E2: Structure benef | F2: Type organisat | G2: Nom responsable | H2: Marque | I2: Modelé | J2: Numéro de série | K2: Telephone | L2: commune_zi | M2: Arrondissement | N2: Année acquisition | O2: Provenance | P2: Financement | Q2: Observations
A3: PODOR | B3: Gamadji Saré | C3: Moissonneuse batteuse VALTRA pneu | D3: Moissonneuse Batteuse | E3: UNION NDIOUM SP1 | F3: Union | G3: Oumar DIAW | H3: VALTRA | K3: 776594761 | L3: NDIOUM | N3: 2019 | O3: MAER | Q3: Bon état
A4: PODOR | B4: Gamadji Saré | C4: Moissonneuse batteuse VALTRA pneu | D4: Moissonneuse Batteuse | E4: Boumatt Agro fresh ABDOU SALL | F4: Individuel | G4: ABDOU SALL | H4: VALTRA | K4: 782115605 | L4: GUEDEVILLAGE | M4: Gamadji sarré | N4: 2015 | O4: PUDC | Q4: Bon état
A5: PODOR | B5: Gamadji Saré | C5: Moissonneuse batteuse Massey Fergusson pneu | D5: Moissonneuse Batteuse | E5: GIE Diokere Endam MOUSSA HAROUNA LY | F5: Individuel | G5: MOUSSA HAROUNA LY | H5: Massey Fergusson | I5: 7240 ACTIVA | K5: 77 647 69 33 | L5: GUEDEVILLAGE | M5: Gamadji sarré | N5: 2016 | O5: MAER | Q5: Bon état
A6: PODOR | B6: Gamadji Saré | C6: tracteur 100 CV +Offset 24 disques | D6: Tracteur | E6: UNION NDIOUM SP2 | F6: Union | G6: Magoum NDIAYE | H6: Autre | I6: DEUTZ-FAHR | J6: 6130W Profi | K6: 775127979 | L6: NDIOUM | M6: Gamadji sarré | N6: 2018 | O6: MAER | Q6: Bon état
A7: PODOR | B7: Gamadji Saré | C7: Tracteur 125CV+Offset 28 disques Jonh deer | D7: Tracteur | E7: Boumatt Agro fresh | F7: Individuel | G7: ABDOU SALL | H7: Jonh Deer | I7: 6125 D | K7: 78 211 56 05 | L7: GUEDEVILLAGE | M7: Gamadji sarré | N7: 2016 | O7: MAER | Q7: Bon état
A8: PODOR | B8: Gamadji Saré | C8: TRACTEUR VALTRA DE 88 CV + PULVERISEUR OFFSET DE 20 DISQUES TRAINE | D8: Tracteur | E8: Union Guédé Village | F8: Union | G8: IBRAHIMA DIAW | H8: VALTRA | I8: A750L | K8: 77 614 24 32 | L8: GUEDEVILLAGE | M8: Gamadji sarré | N8: 2014 | O8: SAED | Q8: Panne | R8: Pont, pignon
A9: PODOR | B9: Gamadji Saré | C9: TRACTEUR VALTRA DE 88 CV + PULVERISEUR OFFSET DE 20 DISQUES TRAINE | D9: Tracteur | E9: Fédération des GIE de Donaye | F9: Union | G9: IBRAHIMA WONE | H9: VALTRA | I9: A750L | K9: 77 351 40 96 | L9: GUEDEVILLAGE | M9: Gamadji sarré | N9: 2014 | O9: SAED | Q9: Panne | R9: Ambrayage
A10: PODOR | B10: Gamadji Saré | C10: Tracteur 125CV+Offset 28 disques Jonh deer | D10: Tracteur | E10: UNION GIE DE DIATTAR | F10: Union | G10: OUSMANE SY | H10: Jonh Deer | I10: 6125 D | K10: 77 948 24 90 | L10: GUEDEVILLAGE | M10: Gamadji sarré | N10: 2015 | O10: MAER | Q10: Bon état
A11: PODOR | B11: Gamadji Saré | C11: Tracteur CASE | D11: Tracteur | E11: UNION GIE DE DIATTAR | F11: Union | G11: Aly Dramane Sy | H11: CASE | K11: 77 907 31 39 | L11: GUEDEVILLAGE | M11: Gamadji sarré | N11: 2024 | O11: Don | Q11: Bon état
A12: PODOR | B12: Gamadji Saré | C12: Tracteur 125CV+Offset 28 disques Jonh deer | D12: Tracteur | E12: UNION GUEDE CHANTIER | F12: Union | G12: CHERIF AMADOU DIOP | H12: Jonh Deer | I12: 6125 D | K12: 77 534 86 22 | L12: GUEDECHANTIER | M12: Gamadji sarré | N12: 2015 | O12: MAER | Q12: Bon état
A13: PODOR | B13: Gamadji Saré | C13: Tracteur 125CV+Offset 28 disques Jonh deer | D13: Tracteur | E13: SOULEYMANE LY MBOYO (PRIVE) | F13: Individuel | G13: SOULEYMANE LY | H13: Jonh Deer | I13: 6125 D | K13: 77 549 04 16 | L13: GUEDEVILLAGE | M13: Gamadji sarré | N13: 2015 | O13: MAER | Q13: Bon état
A14: PODOR | B14: Gamadji Saré | C14: Tracteur John Deer 90 CV + Moissonneuse batteuse portée | D14: Tracteur | E14: GIE Groupe Naforé | F14: Union | G14: ABDOULAYE BA | H14: Jonh Deer | I14: 6125 D | K14: 77 557 58 19 | L14: PODOR | M14: Gamadji sarré | N14: 2016 | O14: MAER | Q14: Bon état
A15: PODOR | B15: Gamadji Saré | C15: Tracteur John Deer 90 CV + Moissonneuse batteuse portée | D15: Tracteur | E15: Boumatt Agro fresh | F15: Individuel | G15: ABDOU SALL | H15: Jonh Deer | I15: 6125 D | K15: 78 211 56 05 | L15: GUEDEVILLAGE | M15: Gamadji sarré | N15: 2016 | O15: MAER | Q15: Bon état
A16: PODOR | B16: Gamadji Saré | C16: tracteur 100 CV +Offset 24 disques | D16: Tracteur | E16: UNION GIE DE MBANTOU | F16: Union | G16: Amadou Moctar BA | H16: Autre | I16: DEUTZ-FAHR | J16: 6130W Profi | K16: 77 442 61 28 | L16: GUEDEVILLAGE | M16: Gamadji sarré | N16: 2018 | O16: MAER | Q16: Bon état
A17: PODOR | B17: Gamadji Saré | C17: tracteur 100 CV +Offset 24 disques | D17: Tracteur | E17: GIE RACINE 2 KODITH | F17: Individuel | G17: ABDOULAYE RACINE ANNE | H17: Autre | I17: DEUTZ-FAHR | J17: 6130W Profi | K17: 77 542 60 18 | L17: GUEDEVILLAGE | M17: Gamadji sarré | N17: 2018 | O17: MAER | Q17: Bon état
A18: PODOR | B18: Gamadji Saré | C18: Tracteur 125CV+Offset 28 disques Jonh deer | D18: Tracteur | E18: GIE Baidy Dieynabel DIOP | F18: Individuel | G18: Elhadji Demba Louboudou DIOP | H18: Jonh Deer | I18: 6125 D | K18: 77 361 922 87 | L18: GUEDECHANTIER | M18: Gamadji sarré | N18: 2016 | O18: MAER | Q18: Bon état
A19: PODOR | B19: Gamadji Saré | C19: Tracteur 125CV+Offset 28 disques Jonh deer | D19: Tracteur | E19: UNION H MAAJE DOUE | F19: Union | G19: ABDOULAYE BA | H19: Jonh Deer | I19: 6125 D | K19: 77 557 58 19 | L19: PODOR | M19: Gamadji sarré | N19: 2015 | O19: MAER | Q19: Bon état
A20: PODOR | B20: Gamadji Saré | C20: Tracteur 125CV+Offset 28 disques Jonh deer | D20: Tracteur | E20: Union thierno Bocar Ly Mboyo 1 | F20: Union | G20: SADIO SALL | H20: Jonh Deer | I20: 6125 D | K20: 77 643 65 32 | L20: GUEDEVILLAGE | M20: Gamadji sarré | N20: 2016 | O20: MAER | Q20: Bon état
A21: PODOR | B21: Gamadji Saré | C21: Tracteur 125CV+Offset 28 disques Jonh deer | D21: Tracteur | E21: UNION DES GIE DE DEMET | F21: Union | G21: KALIDOU AW | H21: Jonh Deer | I21: 6125 D | K21: 77 567 31 13 | L21: DODEL | M21: Gamadji sarré | N21: 2016 | O21: MAER | Q21: Bon état
A22: PODOR | B22: Gamadji Saré | C22: Tracteur 125CV+Offset 28 disques Jonh deer | D22: Tracteur | E22: GIE TIMTIMOL(privé) | F22: Individuel | G22: SAÏDOU NOUROU BA | H22: Jonh Deer | I22: 6125 D | K22: 77-639-67-67 | L22: DODEL | M22: Gamadji sarré | N22: 2016 | O22: MAER | Q22: Bon état
A23: PODOR | B23: Gamadji Saré | C23: Tracteur 125CV+Offset 28 disques Jonh deer | D23: Tracteur | E23: GIE FASSE Mouhamadou lamine DJIGO Demette | F23: Individuel | G23: MOUHAMADOU LAMINE DJIGO | H23: Jonh Deer | I23: 6125 D | K23: 77 412 63 88 | L23: DEMETTE | M23: Gamadji sarré | N23: 2016 | O23: MAER | Q23: Bon état
A24: PODOR | B24: Gamadji Saré | C24: tracteur 100 CV +Offset 24 disques | D24: Tracteur | E24: GIE DARA MARABOUT DARA HALAYBE | F24: Individuel | G24: El Hadji Mamadou Moussa LY | H24: Autre | I24: DEUTZ-FAHR | J24: 6130W Profi | K24: 77 656 24 70 | L24: DODEL | M24: Gamadji sarré | N24: 2018 | O24: MAER | Q24: Bon état
A25: PODOR | B25: Gamadji Saré | C25: tracteur 100 CV +Offset 24 disques | D25: Tracteur | E25: GIE ELIMANE DOBANGUO Demette | F25: Individuel | G25: Mamadou Abdoulaye SOKO | H25: Autre | I25: DEUTZ-FAHR | J25: 6130W Profi | K25: 77 204 64 19 | L25: DEMETTE | M25: Gamadji sarré | N25: 2019 | O25: MAER | Q25: Bon état
A26: PODOR | B26: Thillé Boubacar | C26: Tracteur 125CV+Offset 28 disques Jonh deer | D26: Tracteur | E26: UNION DIOSSOROL NDIAWAR | F26: Union | G26: MOUSSA AW | H26: Jonh Deer | I26: 6125 D | K26: 77 568 13 81 | L26: GUEDEVILLAGE | M26: Thillé Boubacar | N26: 2016 | O26: MAER | Q26: Bon état
A27: PODOR | B27: Thillé Boubacar | C27: Tracteur 125CV+Offset 28 disques Jonh deer | D27: Tracteur | E27: GUIA (Privé) | F27: Individuel | G27: MAMADOU MOUSSA DIACK | H27: Jonh Deer | I27: 6125 D | K27: 77 555 44 57 | L27: GUEDEVILLAGE | M27: Gamadji sarré | N27: 2016 | O27: MAER | Q27: Bon état
A28: PODOR | B28: Gamadji Saré | C28: Tracteur 100CV+Offset 24 disques Dushter et remorque 10 T | D28: Tracteur | E28: Union des Organisations Paysannes Hakoudé Madje de Doué | F28: Union | G28: Malick Amadou Ly | H28: Autre | I28: DEUTZ-FAHR | J28: 6130W Profi | K28: 77 550 24 81 | L28: Guédé village | M28: Gamadji sarré | N28: 2024 | O28: MASAE | P28: LBA | Q28: Bon état | R28: avec offset
A29: PODOR | B29: Gamadji Saré | C29: Tracteur 100 CV + Offset 24 disques + remorque 10 T | D29: Tracteur | E29: Privé | F29: Individuel | G29: MOUSSA HAROUNA LY | H29: Autre | I29: DEUTZ-FAHR | J29: 6130W Profi | K29: 77 647 69 33 | L29: GUEDEVILLAGE | M29: Gamadji sarré | N29: 2024 | O29: MASAE | P29: LBA | Q29: Bon état
A30: PODOR | B30: Gamadji Saré | C30: Tracteur 100 CV + Offset 24 disques + remorque 10 T | D30: Tracteur | E30: Société Coopérative agro sylvo pastoral | F30: Coopérative | G30: Mamadou Niang | H30: Autre | I30: DEUTZ-FAHR | J30: 6130W Profi | K30: 77 722 65 23 | L30: GUEDEVILLAGE | M30: Gamadji sarré | N30: 2024 | O30: MASAE | P30: LBA | Q30: Bon état
A31: PODOR | B31: Gamadji Saré | C31: Tracteur 100CV+Offset 24 disques Dushter et remorque 5 T | D31: Tracteur | E31: RESEPP | F31: Individuel | G31: Mamadou Amadou Ndiaye | H31: Autre | I31: DEUTZ-FAHR | J31: 6130W Profi | K31: 77 515 18 96 | L31: Diatar | M31: Gamadji sarré | N31: 2024 | O31: MASAE | Q31: Notification
A32: PODOR | B32: Gamadji Saré | C32: Moissonneuse batteuse à chenille FM WORLD | D32: Moissonneuse Batteuse | E32: Fédération des GIE de Donaye | F32: Union | G32: Ibrahima Aliou Sylla | H32: FM WORLD | K32: 77 634 52 41 | L32: Guédé village | M32: Gamadji sarré | N32: 2024 | O32: MASAE | P32: LBA | Q32: Bon Etat
A33: PODOR | B33: Gamadji Saré | C33: Moissonneuse batteuse à chenille FM WORLD | D33: Moissonneuse Batteuse | E33: Union des GIE SP2 de Ndioum | F33: Union | G33: Magoum Ndiaye | H33: FM WORLD | K33: 77 512 79 79 | L33: Ndioum | M33: Gamadji sarré | N33: 2024 | O33: MASAE | P33: LBA | Q33: Bon etat
A34: PODOR | B34: Gamadji Saré | C34: Moissonneuse batteuse à chenille FM WORLD | D34: Moissonneuse Batteuse | E34: Union des Produceurs et Agriculteurs de Diatar | F34: Union | G34: Ousmane Sy | H34: FM WORLD | K34: 77 731 46 37 | L34: Guede Village | M34: Gamadji sarré | N34: 2024 | O34: MASAE | Q34: Notification
A35: PODOR | B35: Gamadji Saré | C35: Moissonneuse batteuse à chenille FM WORLD | D35: Moissonneuse Batteuse | E35: Union des PIV de Guédé | F35: Union | G35: Ibrahima Diaw | H35: FM WORLD | K35: 77 614 24 32 | L35: guede village | M35: Gamadji sarré | N35: 2024 | O35: MASAE | P35: LBA | Q35: Bon etat
A36: PODOR | B36: Gamadji Saré | C36: Tracteur Massay Ferguson 180 CV | D36: Tracteur | E36: Union Diomandou | F36: Union | G36: Oumar Wade | H36: Massey Fergusson | I36: MF 6S 180 | K36: 77 524 55 42 | L36: Dodel | M36: Gamadji sarré | N36: 2024 | O36: Don | Q36: Bon état
A37: PODOR | B37: Cas_Cas / Saldé | C37: Tracteur 100CV+Offset 24 disques | D37: Tracteur | E37: Privé | F37: privé | G37: El Hadji Ndiaye | H37: Autre | I37: DEUTZ-FAHR | J37: 6130W Profi | K37: 77 848 02 50 | L37: Dodel | M37: Gamadji sarré | N37: 2025 | Q37: Bon etat
A38: PODOR | B38: Cas_Cas / Saldé | C38: Tracteur 100CV+Offset 24 disques | D38: Tracteur | E38: Privé | F38: privé | G38: El Hadji Tidiane Ly | H38: Autre | I38: DEUTZ-FAHR | J38: 6130W Profi | K38: 77 565 24 70 | L38: Dodel | M38: Gamadji sarré | Q38: Bon etat

Sheet Cas Cas - Saldé
A2: Delegation | B2: Secteur | C2: Caract materiels agricole | D2: type materiel | E2: Structure benef | F2: Type organisat | G2: Nom responsable | H2: Marque | I2: Modelé | J2: Numéro de série | K2: Telephone | L2: commune_zi | M2: Arrondissement | N2: Année acquisition | O2: Provenance | P2: Financement | Q2: Observations
A3: PODOR | B3: Cas_Cas / Saldé | C3: Moissonneuse batteuse Massey Fergusson pneu | D3: Moissonneuse Batteuse | E3: Union SP2 Aeré Lao | F3: Union | G3: Amadou Tidiane Dème | H3: Massey Fergusson | I3: 32 Advanced | K3: 775567586 | L3: AERE LAO | M3: Cas cas | N3: 2021 | O3: Fédération | P3: LBA | Q3: Bon Etat
A4: PODOR | B4: Cas_Cas / Saldé | C4: Moissonneuse batteuse Massey Fergusson pneu | D4: Moissonneuse Batteuse | E4: FUGIAM | F4: Fédération | G4: Samba THIAM | H4: Massey Fergusson | I4: 32 Advanced | K4: 775715290 | L4: MEDINA NDIATHBE | M4: Cas cas | N4: 2019 | O4: MAER | Q4: Bon état
A5: PODOR | B5: Cas_Cas / Saldé | C5: Tracteur 132 CV + Offset 26 disques traine VALTRA | D5: Tracteur | E5: Union des GIE de Madina | F5: Union | G5: YAYA SOULEYMANE DEME | H5: VALTRA | I5: BM 125I | K5: 775472784 | L5: GOLLERE | M5: Cas cas | N5: 2014 | O5: SAED | Q5: Panne
A6: PODOR | B6: Cas_Cas / Saldé | C6: Tracteur 125CV+Offset 28 disques Jonh deer | D6: Tracteur | E6: PELLITAL (prestataire Aéré) | F6: Individuel | G6: AMADOU THIAM | H6: Jonh Deer | I6: 6125 D | K6: 77 567 03 11 | L6: AERELAO | M6: Cas cas | N6: 2016 | O6: MAER | Q6: Bon état
A7: PODOR | B7: Cas_Cas / Saldé | C7: Tracteur 125CV+Offset 28 disques Jonh deer | D7: Tracteur | E7: UNION MBOLO BIRANE | F7: Union | G7: OUSMANE AMADOU KANE | H7: Jonh Deer | I7: 6125 D | K7: 77 560 29 15 | L7: MBOLOBIRANE | M7: Cas cas | N7: 2015 | O7: MAER | Q7: Panne
A8: PODOR | B8: Cas_Cas / Saldé | C8: Tracteur 125CV+Offset 28 disques Jonh deer | D8: Tracteur | E8: UNION YIRLAABE THIKITE | F8: Union | G8: CIRADJI BA | H8: Jonh Deer | I8: 6125 D | K8: 77 565 00 01 | L8: BOKE DIALLOUBE | M8: Cas cas | N8: 2015 | O8: MAER | Q8: Panne
A9: PODOR | B9: Cas_Cas / Saldé | C9: Tracteur 125CV+Offset 28 disques Jonh deer | D9: Tracteur | E9: Union Djigadji Mery | F9: Union | G9: SAMBA BARA SOW | H9: Jonh Deer | I9: 6125 D | K9: 77 564 99 08 | L9: MERY | M9: Cas cas | N9: 2016 | O9: MAER | Q9: Bon état
A10: PODOR | B10: Cas_Cas / Saldé | C10: TRACTEUR VALTRA DE 88 CV + PULVERISEUR OFFSET DE 20 DISQUES TRAINE | D10: Tracteur | E10: Gie WEYNDE DIENG | F10: Individuel | G10: COUMBA IFRA DIENG | H10: VALTRA | I10: A750L | K10: 776465896 | L10: WALALDE | M10: Cas cas | N10: 2014 | O10: SAED | Q10: Panne
A11: PODOR | B11: Cas_Cas / Saldé | C11: TRACTEUR VALTRA DE 88 CV + PULVERISEUR OFFSET DE 20 DISQUES TRAINE | D11: Tracteur | E11: Union de Cas-Cas | F11: Union | G11: SAMBA MOUSSA THIAM | H11: VALTRA | I11: A750L | K11: 77 571 52 90 | L11: MEDINANDIATHBE | M11: Cas cas | N11: 2014 | O11: SAED | Q11: Panne
A12: PODOR | B12: Cas_Cas / Saldé | C12: Tracteur 100 CV +Offset 24 disques | D12: Tracteur | E12: UNION DES GIE DU VILLAGE DE CAS -CAS | F12: Union | G12: Moussa Samba DIAW | H12: DEUTZ-FAHR | I12: 6130W Profi | K12: 775399560 | L12: MEDINA NDIATHBE | M12: Cas cas | N12: 2018 | O12: MAER | Q12: En panne
A13: PODOR | B13: Cas_Cas / Saldé | C13: tracteur 100 CV +Offset 24 disques | D13: Tracteur | E13: UNION GIE DE THIOUBALEL | F13: Union | G13: Yoro SY / 78 569 35 22 | H13: DEUTZ-FAHR | I13: 6130W Profi | K13: 775624283 | L13: MEDINA NDIATHBE | M13: Cas cas | N13: 2018 | O13: MAER | Q13: Moyen
A14: PODOR | B14: Cas_Cas / Saldé | C14: Tracteur 100CV+Offset 24 disques Dushter et remorque 5 T | D14: Tracteur | E14: FRA PSE | F14: Individuel | G14: FATIMATA GAYE | H14: DEUTZ-FAHR | I14: 6130W Profi | K14: 77 103 30 56 | L14: Médina diatebé | M14: Cas cas | N14: 2024 | O14: MASAE | P14: LBA | Q14: Bon Etat
A15: PODOR | B15: Cas_Cas / Saldé | C15: Tracteur 100CV+Offset 24 disques Dushter et remorque 10 T | D15: Tracteur | E15: Union des GIE Yirlabé Saldé Ouallah | F15: Union | H15: DEUTZ-FAHR | I15: 6130W Profi | K15: 77 519 26 44 | L15: Boki Dialloubé | M15: Saldé | N15: 2024 | O15: MASAE | Q15: Notification
A16: PODOR | B16: Cas_Cas / Saldé | C16: Tracteur 100CV+Offset 24 disques Dushter et remorque 10 T | D16: Tracteur | E16: Union des GIE de Aéré Lao SP 2 | F16: Union | G16: Amadou Tidiane Dème | H16: DEUTZ-FAHR | I16: 6130W Profi | K16: 77 556 75 86 | L16: Aéré Lao | M16: Cas cas | N16: 2024 | O16: MASAE | P16: LBA | Q16: Bon Etat | R16: avec offset
A17: PODOR | B17: Cas_Cas / Saldé | C17: Moissonneuse batteuse à chenille FM WORLD | D17: Moissonneuse Batteuse | E17: Union des GIE de Aéré Lao SP 2 | F17: Union | G17: Amadou Tidiane Dème | H17: FM WORLD | I17: RUILONG | J17: 4LZ-4.0E | K17: 77 556 75 86 | L17: Aéré lao | M17: Cas cas | N17: 2024 | O17: MASAE | P17: LBA | Q17: Bon Etat
A18: PODOR | B18: Cas_Cas / Saldé | C18: Tracteur 120 CV + offset 26 disques+Remorque 10T | D18: Tracteur | E18: Union wodoss | F18: Union | G18: ABOUBACRY SY | H18: DEUTZ-FAHR | I18: 6130W Profi | K18: 775128501 | L18: PETE | M18: Saldé | N18: 2024 | O18: MASAE | P18: LBA | Q18: Bon Etat | R18: sans offset
A19: PODOR | B19: Cas_Cas / Saldé | D19: Tracteur | E19: UAI 4 SALDE | F19: Union | G19: ALLASANE DIA | H19: DEUTZ-FAHR | I19: 6130W Profi | K19: 774070332 | L19: BOKE DIALLOUBE | M19: Saldé | N19: 2024 | O19: MASAE | P19: LBA | Q19: Bon Etat | R19: avec offset
A20: PODOR | B20: Cas_Cas / Saldé | C20: Tracteur 100CV+Offset 24 disques Dushter et remorque 10 T | D20: Tracteur | E20: UNION SALDE | F20: Union | G20: IBRAHIMA HANN | H20: DEUTZ-FAHR | I20: 6130W Profi | K20: 775714906 | L20: BOKKE DIALLOUBE | M20: SALDE | N20: 2024 | O20: MASAE | P20: LBA | Q20: Bon Etat | R20: avec offset
A21: PODOR | B21: Cas_Cas / Saldé | C21: Tracteur 100CV+Offset 24 disques | D21: Tracteur | E21: GIE BIDIEW | F21: Individuel | G21: Thioye Fils | H21: DEUTZ-FAHR | I21: 6130W Profi | L21: AERELAO | M21: Cas cas | N21: 2019 | O21: MASAE | Q21: Bon Etat

Sheet Raw Data
A1: Delegation | B1: Secteur | C1: Caract materiels agricole | D1: type materiel | E1: Structure benef | F1: Type organisat | G1: Nom responsable | H1: Telephone | I1: commune_zi | J1: Arrondissement | K1: Année acquisition | L1: Provenance | M1: Financement | N1: Observations
A2: PODOR | B2: Cas Cas / Saldé | C2: Moissonneuse batteuse Massey Fergusson pneu | D2: Combine Harvester | E2: Union SP2 Aeré Lao | F2: Union | G2: Amadou Tidiane Dème | H2: 775567586 | I2: Aéré Lao | J2: Cas cas | K2: 2021 | L2: Fédération | M2: LBA | N2: Function
A3: PODOR | B3: Cas Cas / Saldé | C3: Tracteur 125CV+Offset 28 disques Jonh deer | D3: Tractor | E3: PELLITAL (prestataire Aéré) | F3: Private | G3: AMADOU THIAM | H3: 77 567 03 11 | I3: Aéré Lao | J3: Cas cas | K3: 2016 | L3: MAER | N3: Function
A4: PODOR | B4: Cas Cas / Saldé | C4: Tracteur 100CV+Offset 24 disques Dushter et remorque 10 T | D4: Tractor | E4: Union des GIE de Aéré Lao SP 2 | F4: Union | G4: Amadou Tidiane Dème | H4: 77 556 75 86 | I4: Aéré Lao | J4: Cas cas | K4: 2024 | L4: MASAE | M4: LBA | N4: Function
A5: PODOR | B5: Cas Cas / Saldé | C5: Moissonneuse batteuse à chenille FM WORLD | D5: Combine Harvester | E5: Union des GIE de Aéré Lao SP 2 | F5: Union | G5: Amadou Tidiane Dème | H5: 77 556 75 86 | I5: Aéré Lao | J5: Cas cas | K5: 2024 | L5: MASAE | M5: LBA | N5: Function
A6: PODOR | B6: Cas Cas / Saldé | C6: Tracteur 100CV+Offset 24 disques | D6: Tractor | E6: GIE BIDIEW | F6: Private | G6: Thioye Fils | I6: Aéré Lao | J6: Cas cas | K6: 2019 | L6: MASAE | N6: Function
A7: PODOR | B7: Cas Cas / Saldé | C7: Tracteur 125CV+Offset 28 disques Jonh deer | D7: Tractor | E7: UNION YIRLAABE THIKITE | F7: Union | G7: CIRADJI BA | H7: 77 565 00 01 | I7: Boké Dialloubé | J7: Cas cas | K7: 2015 | L7: MAER | N7: Breakdown
A8: PODOR | B8: Cas Cas / Saldé | C8: Tracteur 100CV+Offset 24 disques Dushter et remorque 10 T | D8: Tractor | E8: Union des GIE Yirlabé Saldé Ouallah | F8: Union | H8: 77 519 26 44 | I8: Boké Dialloubé | J8: Saldé | K8: 2024 | L8: MASAE | N8: Function
A9: PODOR | B9: Cas Cas / Saldé | D9: Tractor | E9: UAI 4 SALDE | F9: Union | G9: ALLASANE DIA | H9: 774070332 | I9: Boké Dialloubé | J9: Saldé | K9: 2024 | L9: MASAE | M9: LBA | N9: Function
A10: PODOR | B10: Cas Cas / Saldé | C10: Tracteur 100CV+Offset 24 disques Dushter et remorque 10 T | D10: Tractor | E10: UNION SALDE | F10: Union | G10: IBRAHIMA HANN | H10: 775714906 | I10: Boké Dialloubé | J10: SALDE | K10: 2024 | L10: MASAE | M10: LBA | N10: Function
A11: PODOR | B11: Cas Cas / Saldé | C11: Moissonneuse batteuse Massey Fergusson pneu | D11: Combine Harvester | E11: FUGIAM | F11: Union | G11: Samba THIAM | H11: 775715290 | I11: Madina Diathbé | J11: Cas cas | K11: 2019 | L11: MAER | N11: Function
A12: PODOR | B12: Cas Cas / Saldé | C12: TRACTEUR VALTRA DE 88 CV + PULVERISEUR OFFSET DE 20 DISQUES TRAINE | D12: Tractor | E12: Union de Cas-Cas | F12: Union | G12: SAMBA MOUSSA THIAM | H12: 77 571 52 90 | I12: Madina Diathbé | J12: Cas cas | K12: 2014 | L12: SAED | N12: Breakdown
A13: PODOR | B13: Cas Cas / Saldé | C13: Tracteur 100 CV +Offset 24 disques | D13: Tractor | E13: UNION DES GIE DU VILLAGE DE CAS -CAS | F13: Union | G13: Moussa Samba DIAW | H13: 775399560 | I13: Madina Diathbé | J13: Cas cas | K13: 2018 | L13: MAER | N13: Breakdown
A14: PODOR | B14: Cas Cas / Saldé | C14: tracteur 100 CV +Offset 24 disques | D14: Tractor | E14: UNION GIE DE THIOUBALEL | F14: Union | G14: Yoro SY / 78 569 35 22 | H14: 775624283 | I14: Madina Diathbé | J14: Cas cas | K14: 2018 | L14: MAER | N14: Function
A15: PODOR | B15: Cas Cas / Saldé | C15: Tracteur 100CV+Offset 24 disques Dushter et remorque 5 T | D15: Tractor | E15: FRA PSE | F15: Private | G15: FATIMATA GAYE | H15: 77 103 30 56 | I15: Madina Diathbé | J15: Cas cas | K15: 2024 | L15: MASAE | M15: LBA | N15: Function
A16: PODOR | B16: Cas Cas / Saldé | C16: Tracteur 125CV+Offset 28 disques Jonh deer | D16: Tractor | E16: UNION MBOLO BIRANE | F16: Union | G16: OUSMANE AMADOU KANE | H16: 77 560 29 15 | I16: Mbolo Birane | J16: Cas cas | K16: 2015 | L16: MAER | N16: Breakdown
A17: PODOR | B17: Cas Cas / Saldé | C17: Tracteur 125CV+Offset 28 disques Jonh deer | D17: Tractor | E17: Union Djigadji Mery | F17: Union | G17: SAMBA BARA SOW | H17: 77 564 99 08 | I17: Méry | J17: Cas cas | K17: 2016 | L17: MAER | N17: Function
A18: PODOR | B18: Cas Cas / Saldé | C18: Tracteur 120 CV + offset 26 disques+Remorque 10T | D18: Tractor | E18: Union des GIE de wodoss | F18: Union | G18: ABOUBACRY SY | H18: 775128501 | I18: Pété | J18: Saldé | K18: 2024 | L18: MASAE | M18: LBA | N18: Function
A19: PODOR | B19: Cas Cas / Saldé | C19: TRACTEUR VALTRA DE 88 CV + PULVERISEUR OFFSET DE 20 DISQUES TRAINE | D19: Tractor | E19: Gie WEYNDE DIENG | F19: Private | G19: COUMBA IFRA DIENG | H19: 776465896 | I19: Walaldé | J19: Cas cas | K19: 2014 | L19: SAED | N19: Breakdown
A20: PODOR | B20: Cas_Cas / Saldé | C20: Tracteur 132 CV + Offset 26 disques traine VALTRA | D20: Tractor | E20: Union des GIE de Madina | F20: Union | G20: YAYA SOULEYMANE DEME | H20: 775472784 | I20: Golléré | J20: Cas cas | K20: 2014 | L20: SAED | N20: Breakdown
A21: PODOR | B21: Gamadji Saré | C21: Tracteur 125CV+Offset 28 disques Jonh deer | D21: Tractor | E21: GIE FASSE Mouhamadou lamine DJIGO Demette | F21: Private | G21: MOUHAMADOU LAMINE DJIGO | H21: 77 412 63 88 | I21: Démette | J21: Gamadji sarré | K21: 2016 | L21: MAER | N21: Function
A22: PODOR | B22: Gamadji Saré | C22: tracteur 100 CV +Offset 24 disques | D22: Tractor | E22: GIE ELIMANE DOBANGUO Demette | F22: Private | G22: Mamadou Abdoulaye SOKO | H22: 77 204 64 19 | I22: Démette | J22: Gamadji sarré | K22: 2019 | L22: MAER | N22: Function
A23: PODOR | B23: Gamadji Saré | C23: Tracteur 100CV+Offset 24 disques Dushter et remorque 5 T | D23: Tractor | E23: RESEPP | F23: Private | G23: Mamadou Amadou Ndiaye | H23: 77 515 18 96 | I23: Démette | J23: Gamadji sarré | K23: 2024 | L23: MASAE | N23: Function
A24: PODOR | B24: Gamadji Saré | C24: Tracteur 100CV+Offset 24 disques | D24: Tractor | E24: Privé | F24: Private | G24: El Hadji Ndiaye | H24: 77 848 02 50 | I24: Dodel | J24: Gamadji sarré | K24: 2025 | N24: Function
A25: PODOR | B25: Gamadji Saré | C25: Tracteur 100CV+Offset 24 disques | D25: Tractor | E25: Privé | F25: Private | G25: El Hadji Tidiane Ly | H25: 77 565 24 70 | I25: Dodel | J25: Gamadji sarré | K25: N/A | N25: Function
A26: PODOR | B26: Gamadji Saré | C26: Tracteur 125CV+Offset 28 disques Jonh deer | D26: Tractor | E26: UNION DES GIE DE DEMET | F26: Union | G26: KALIDOU AW | H26: 77 567 31 13 | I26: Dodel | J26: Gamadji sarré | K26: 2016 | L26: MAER | N26: Function | O26: Pont, pignon
A27: PODOR | B27: Gamadji Saré | C27: Tracteur 125CV+Offset 28 disques Jonh deer | D27: Tractor | E27: GIE TIMTIMOL(privé) | F27: Private | G27: SAÏDOU NOUROU BA | H27: 77-639-67-67 | I27: Dodel | J27: Gamadji sarré | K27: 2016 | L27: MAER | N27: Function | O27: Ambrayage
A28: PODOR | B28: Gamadji Saré | C28: tracteur 100 CV +Offset 24 disques | D28: Tractor | E28: GIE DARA MARABOUT DARA HALAYBE | F28: Private | G28: El Hadji Mamadou Moussa LY | H28: 77 656 24 70 | I28: Dodel | J28: Gamadji sarré | K28: 2018 | L28: MAER | N28: Function
A29: PODOR | B29: Gamadji Saré | C29: Tracteur Massay Ferguson 180 CV | D29: Tractor | E29: Union Diomandou | F29: Union | G29: Oumar Wade | H29: 77 524 55 42 | I29: Dodel | J29: Gamadji sarré | K29: 2024 | L29: Don | N29: Function
A30: PODOR | B30: Gamadji Saré | C30: Moissonneuse batteuse à chenille FM WORLD | D30: Combine Harvester | E30: Union des Produceurs et Agriculteurs de Diatar | F30: Union | G30: Ousmane Sy | H30: 77 731 46 37 | I30: Guede Village | J30: Gamadji sarré | K30: 2024 | L30: MASAE | N30: Function
A31: PODOR | B31: Gamadji Saré | C31: Moissonneuse batteuse VALTRA pneu | D31: Combine Harvester | E31: Boumatt Agro fresh ABDOU SALL | F31: Private | G31: ABDOU SALL | H31: 782115605 | I31: Guede Village | J31: Gamadji sarré | K31: 2015 | L31: PUDC | N31: Function
A32: PODOR | B32: Gamadji Saré | C32: Moissonneuse batteuse Massey Fergusson | D32: Combine Harvester | E32: GIE Diokere Endam MOUSSA HAROUNA LY | F32: Private | G32: MOUSSA HAROUNA LY | H32: 77 647 69 33 | I32: Guede Village | J32: Gamadji sarré | K32: 2016 | L32: MAER | N32: Function
A33: PODOR | B33: Gamadji Saré | C33: Tracteur 125CV+Offset 28 disques Jonh deer | D33: Tractor | E33: Boumatt Agro fresh | F33: Private | G33: ABDOU SALL | H33: 78 211 56 05 | I33: Guede Village | J33: Gamadji sarré | K33: 2016 | L33: MAER | N33: Function
A34: PODOR | B34: Gamadji Saré | C34: TRACTEUR VALTRA DE 88 CV + PULVERISEUR OFFSET DE 20 DISQUES TRAINE | D34: Tractor | E34: Union Guédé Village | F34: Union | G34: IBRAHIMA DIAW | H34: 77 614 24 32 | I34: Guede Village | J34: Gamadji sarré | K34: 2014 | L34: SAED | N34: Breakdown
A35: PODOR | B35: Gamadji Saré | C35: TRACTEUR VALTRA DE 88 CV + PULVERISEUR OFFSET DE 20 DISQUES TRAINE | D35: Tractor | E35: Fédération des GIE de Donaye | F35: Union | G35: IBRAHIMA WONE | H35: 77 351 40 96 | I35: Guede Village | J35: Gamadji sarré | K35: 2014 | L35: SAED | N35: Breakdown
A36: PODOR | B36: Gamadji Saré | C36: Tracteur 125CV+Offset 28 disques Jonh deer | D36: Tractor | E36: UNION GIE DE DIATTAR | F36: Union | G36: OUSMANE SY | H36: 77 948 24 90 | I36: Guede Village | J36: Gamadji sarré | K36: 2015 | L36: MAER | N36: Function
A37: PODOR | B37: Gamadji Saré | C37: Tracteur CASE | D37: Tractor | E37: UNION GIE DE DIATTAR | F37: Union | G37: Aly Dramane Sy | H37: 77 907 31 39 | I37: Guede Village | J37: Gamadji sarré | K37: 2024 | L37: Don | N37: Function
A38: PODOR | B38: Gamadji Saré | C38: Tracteur 125CV+Offset 28 disques Jonh deer | D38: Tractor | E38: UNION GUEDE CHANTIER | F38: Union | G38: CHERIF AMADOU DIOP | H38: 77 534 86 22 | I38: Guede Village | J38: Gamadji sarré | K38: 2015 | L38: MAER | N38: Function
A39: PODOR | B39: Gamadji Saré | C39: Tracteur 125CV+Offset 28 disques Jonh deer | D39: Tractor | E39: SOULEYMANE LY MBOYO (PRIVE) | F39: Private | G39: SOULEYMANE LY | H39: 77 549 04 16 | I39: Guede Village | J39: Gamadji sarré | K39: 2015 | L39: MAER | N39: Function
A40: PODOR | B40: Gamadji Saré | C40: Tracteur John Deer 90 CV + Moissonneuse batteuse portée | D40: Tractor | E40: Boumatt Agro fresh | F40: Private | G40: ABDOU SALL | H40: 78 211 56 05 | I40: Guede Village | J40: Gamadji sarré | K40: 2016 | L40: MAER | N40: Function
...

Sheet ->Analysis

Sheet Analysis
A1: Inventory Result (Podor)
A2: Type of Machine
A3: Type of Machine | D3: Number of Machine
A4: Tractor | D4: =COUNTIF('Raw Data'!$D$2:$D$92,Analysis!A4) -> 69
A5: Combine Harvester | D5: =COUNTIF('Raw Data'!$D$2:$D$92,Analysis!A5) -> 22
A6: Total | D6: =SUM(D4:D5) -> 91
A8: Type of Owner
A9: Type of Owner | D9: Type of Machine | F9: Number of Owner | G9: Possetion Rate of Owner
A10: Union | D10: Tractor | F10: =COUNTIFS('Raw Data'!$F$2:$F$92,Analysis!A10,'Raw Data'!$D$2:$D$92,Analysis!D10) -> 42 | G10: =ROUND(F10/$D$4,2) -> 0.61
A11: Union | D11: Combine Harvester | F11: =COUNTIFS('Raw Data'!$F$2:$F$92,Analysis!A11,'Raw Data'!$D$2:$D$92,Analysis!D11) -> 15 | G11: =ROUND(F11/$D$5,2) -> 0.68
A12: Sub-total | F12: =SUM(F10:F11) -> 57 | G12: -
A13: Private | D13: Tractor | F13: =COUNTIFS('Raw Data'!$F$2:$F$92,Analysis!A13,'Raw Data'!$D$2:$D$92,Analysis!D13) -> 25 | G13: =ROUND(F13/$D$4,2) -> 0.36
A14: Private | D14: Combine Harvester | F14: =COUNTIFS('Raw Data'!$F$2:$F$92,Analysis!A14,'Raw Data'!$D$2:$D$92,Analysis!D14) -> 4 | G14: =ROUND(F14/$D$5,2) -> 0.18
A15: Sub-total | F15: =SUM(F13:F14) -> 29 | G15: -
A16: Cooperative | D16: Tractor | F16: =COUNTIFS('Raw Data'!$F$2:$F$92,Analysis!A16,'Raw Data'!$D$2:$D$92,Analysis!D16) -> 2 | G16: =ROUND(F16/$D$4,2) -> 0.03
A17: Cooperative | D17: Combine Harvester | F17: =COUNTIFS('Raw Data'!$F$2:$F$92,Analysis!A17,'Raw Data'!$D$2:$D$92,Analysis!D17) -> 3 | G17: =ROUND(F17/$D$5,2) -> 0.14
A18: Sub-total | F18: =SUM(F16:F17) -> 5 | G18: -
A19: Total | F19: =SUMIF(A10:A18,"Sub-total",F10:F18) -> 91 | G19: -
A21: Operational Situation of Machine
A22: Operation Situation | D22: Type of Machine | F22: Number of Operational Machine | G22: Operational Rate
A23: Function | D23: Tractor | F23: =COUNTIFS('Raw Data'!$N$2:$N$92,Analysis!A23,'Raw Data'!$D$2:$D$92,Analysis!D23) -> 58 | G23: =ROUND(F23/$D$4,2) -> 0.84
A24: Function | D24: Combine Harvester | F24: =COUNTIFS('Raw Data'!$N$2:$N$92,Analysis!A24,'Raw Data'!$D$2:$D$92,Analysis!D24) -> 19 | G24: =ROUND(F24/$D$5,2) -> 0.86
A25: Sub-total | F25: =SUM(F23:F24) -> 77 | G25: -
A26: Breakdown | D26: Tractor | F26: =COUNTIFS('Raw Data'!$N$2:$N$92,Analysis!A26,'Raw Data'!$D$2:$D$92,Analysis!D26) -> 11 | G26: =ROUND(F26/$D$4,2) -> 0.16
A27: Breakdown | D27: Combine Harvester | F27: =COUNTIFS('Raw Data'!$N$2:$N$92,Analysis!A27,'Raw Data'!$D$2:$D$92,Analysis!D27) -> 3 | G27: =ROUND(F27/$D$5,2) -> 0.14
A28: Sub-total | F28: =SUM(F26:F27) -> 14 | G28: -
A29: Total | F29: =SUMIF(A20:A28,"Sub-total",F20:F28) -> 91 | G29: -
A31: Owner-basis Operational Situation of Tractor
A32: Type of Owner | D32: Operation Situation | E32: Type of Machine | F32: Number of Operational Machine | G32: Operational Rate
A33: Union | D33: Function | E33: Tractor | F33: =COUNTIFS('Raw Data'!$F$2:$F$92,Analysis!A33,'Raw Data'!$N$2:$N$92,Analysis!D33,'Raw Data'!$D$2:$D$92,Analysis!E33) -> 33 | G33: =ROUND(F33/$F$35,2) -> 0.79
A34: Union | D34: Breakdown | E34: Tractor | F34: =COUNTIFS('Raw Data'!$F$2:$F$92,Analysis!A34,'Raw Data'!$N$2:$N$92,Analysis!D34,'Raw Data'!$D$2:$D$92,Analysis!E34) -> 9 | G34: =ROUND(F34/$F$35,2) -> 0.21
A35: Sub-total | F35: =SUM(F33:F34) -> 42 | G35: -
A36: Private | D36: Function | E36: Tractor | F36: =COUNTIFS('Raw Data'!$F$2:$F$92,Analysis!A36,'Raw Data'!$N$2:$N$92,Analysis!D36,'Raw Data'!$D$2:$D$92,Analysis!E36) -> 23 | G36: =ROUND(F36/$F$38,2) -> 0.92
A37: Private | D37: Breakdown | E37: Tractor | F37: =COUNTIFS('Raw Data'!$F$2:$F$92,Analysis!A37,'Raw Data'!$N$2:$N$92,Analysis!D37,'Raw Data'!$D$2:$D$92,Analysis!E37) -> 2 | G37: =ROUND(F37/$F$38,2) -> 0.08
A38: Sub-total | F38: =SUM(F36:F37) -> 25 | G38: -
A39: Cooperative | D39: Function | E39: Tractor | F39: =COUNTIFS('Raw Data'!$F$2:$F$92,Analysis!A39,'Raw Data'!$N$2:$N$92,Analysis!D39,'Raw Data'!$D$2:$D$92,Analysis!E39) -> 2 | G39: =ROUND(F39/$F$41,2) -> 1
A40: Cooperative | D40: Breakdown | E40: Tractor | F40: =COUNTIFS('Raw Data'!$F$2:$F$92,Analysis!A40,'Raw Data'!$N$2:$N$92,Analysis!D40,'Raw Data'!$D$2:$D$92,Analysis!E40) -> 0 | G40: =ROUND(F40/$F$41,2) -> 0
A41: Sub-total | F41: =SUM(F39:F40) -> 2 | G41: -
A43: Owner-basis Operational Situation of Combine Harvester
A44: Type of Owner | D44: Operation Situation | E44: Type of Machine | F44: Number of Operational Machine | G44: Operational Rate
...

Sheet Analysis_Commune
A1: Nombre de tracteurs
A2: Secteur | B2: Commune | C2: Type materiel | D2: Type materiel | E2: Nombre de tracteurs
E3: Bon état | F3: Panne
E4: Function | F4: Breakdown
A5: Thillé Boubacar | B5: Fanaye | C5: Tracteur | D5: Tractor | E5: =COUNTIFS('Raw Data'!$I$2:$I$92,Analysis_Commune!$B5,'Raw Data'!$D$2:$D$92,Analysis_Commune!$D5,'Raw Data'!$N$2:$N$92,Analysis_Commune!E$4) -> 5 | F5: =COUNTIFS('Raw Data'!$I$2:$I$92,Analysis_Commune!$B5,'Raw Data'!$D$2:$D$92,Analysis_Commune!$D5,'Raw Data'!$N$2:$N$92,Analysis_Commune!F$4) -> 1
A6: Thillé Boubacar | B6: Ndiayenne Pendao | C6: Tracteur | D6: Tractor | E6: =COUNTIFS('Raw Data'!$I$2:$I$92,Analysis_Commune!$B6,'Raw Data'!$D$2:$D$92,Analysis_Commune!$D6,'Raw Data'!$N$2:$N$92,Analysis_Commune!E$4) -> 14 | F6: =COUNTIFS('Raw Data'!$I$2:$I$92,Analysis_Commune!$B6,'Raw Data'!$D$2:$D$92,Analysis_Commune!$D6,'Raw Data'!$N$2:$N$92,Analysis_Commune!F$4) -> 2
A7: Thillé Boubacar | B7: Niandane | C7: Tracteur | D7: Tractor | E7: =COUNTIFS('Raw Data'!$I$2:$I$92,Analysis_Commune!$B7,'Raw Data'!$D$2:$D$92,Analysis_Commune!$D7,'Raw Data'!$N$2:$N$92,Analysis_Commune!E$4) -> 1 | F7: =COUNTIFS('Raw Data'!$I$2:$I$92,Analysis_Commune!$B7,'Raw Data'!$D$2:$D$92,Analysis_Commune!$D7,'Raw Data'!$N$2:$N$92,Analysis_Commune!F$4) -> 0
A8: Sous-total | E8: =SUM(E5:E7) -> 20 | F8: =SUM(F5:F7) -> 3
A9: Gamadji Saré | B9: Démette | C9: Tracteur | D9: Tractor | E9: =COUNTIFS('Raw Data'!$I$2:$I$92,Analysis_Commune!$B9,'Raw Data'!$D$2:$D$92,Analysis_Commune!$D9,'Raw Data'!$N$2:$N$92,Analysis_Commune!E$4) -> 3 | F9: =COUNTIFS('Raw Data'!$I$2:$I$92,Analysis_Commune!$B9,'Raw Data'!$D$2:$D$92,Analysis_Commune!$D9,'Raw Data'!$N$2:$N$92,Analysis_Commune!F$4) -> 0
A10: Gamadji Saré | B10: Dodel | C10: Tracteur | D10: Tractor | E10: =COUNTIFS('Raw Data'!$I$2:$I$92,Analysis_Commune!$B10,'Raw Data'!$D$2:$D$92,Analysis_Commune!$D10,'Raw Data'!$N$2:$N$92,Analysis_Commune!E$4) -> 6 | F10: =COUNTIFS('Raw Data'!$I$2:$I$92,Analysis_Commune!$B10,'Raw Data'!$D$2:$D$92,Analysis_Commune!$D10,'Raw Data'!$N$2:$N$92,Analysis_Commune!F$4) -> 0
A11: Gamadji Saré | B11: Guede Village | C11: Tracteur | D11: Tractor | E11: =COUNTIFS('Raw Data'!$I$2:$I$92,Analysis_Commune!$B11,'Raw Data'!$D$2:$D$92,Analysis_Commune!$D11,'Raw Data'!$N$2:$N$92,Analysis_Commune!E$4) -> 15 | F11: =COUNTIFS('Raw Data'!$I$2:$I$92,Analysis_Commune!$B11,'Raw Data'!$D$2:$D$92,Analysis_Commune!$D11,'Raw Data'!$N$2:$N$92,Analysis_Commune!F$4) -> 2
A12: Gamadji Saré | B12: Ndioum | C12: Tracteur | D12: Tractor | E12: =COUNTIFS('Raw Data'!$I$2:$I$92,Analysis_Commune!$B12,'Raw Data'!$D$2:$D$92,Analysis_Commune!$D12,'Raw Data'!$N$2:$N$92,Analysis_Commune!E$4) -> 1 | F12: =COUNTIFS('Raw Data'!$I$2:$I$92,Analysis_Commune!$B12,'Raw Data'!$D$2:$D$92,Analysis_Commune!$D12,'Raw Data'!$N$2:$N$92,Analysis_Commune!F$4) -> 0
A13: Gamadji Saré | B13: Podor | C13: Tracteur | D13: Tractor | E13: =COUNTIFS('Raw Data'!$I$2:$I$92,Analysis_Commune!$B13,'Raw Data'!$D$2:$D$92,Analysis_Commune!$D13,'Raw Data'!$N$2:$N$92,Analysis_Commune!E$4) -> 3 | F13: =COUNTIFS('Raw Data'!$I$2:$I$92,Analysis_Commune!$B13,'Raw Data'!$D$2:$D$92,Analysis_Commune!$D13,'Raw Data'!$N$2:$N$92,Analysis_Commune!F$4) -> 0
A14: Sous-total | E14: =SUM(E9:E13) -> 28 | F14: =SUM(F9:F13) -> 2
A15: Cas Cas / Saldé | B15: Aéré Lao | C15: Tracteur | D15: Tractor | E15: =COUNTIFS('Raw Data'!$I$2:$I$92,Analysis_Commune!$B15,'Raw Data'!$D$2:$D$92,Analysis_Commune!$D15,'Raw Data'!$N$2:$N$92,Analysis_Commune!E$4) -> 3 | F15: =COUNTIFS('Raw Data'!$I$2:$I$92,Analysis_Commune!$B15,'Raw Data'!$D$2:$D$92,Analysis_Commune!$D15,'Raw Data'!$N$2:$N$92,Analysis_Commune!F$4) -> 0
A16: Cas Cas / Saldé | B16: Boké Dialloubé | C16: Tracteur | D16: Tractor | E16: =COUNTIFS('Raw Data'!$I$2:$I$92,Analysis_Commune!$B16,'Raw Data'!$D$2:$D$92,Analysis_Commune!$D16,'Raw Data'!$N$2:$N$92,Analysis_Commune!E$4) -> 3 | F16: =COUNTIFS('Raw Data'!$I$2:$I$92,Analysis_Commune!$B16,'Raw Data'!$D$2:$D$92,Analysis_Commune!$D16,'Raw Data'!$N$2:$N$92,Analysis_Commune!F$4) -> 1
A17: Cas Cas / Saldé | B17: Madina Diathbé | C17: Tracteur | D17: Tractor | E17: =COUNTIFS('Raw Data'!$I$2:$I$92,Analysis_Commune!$B17,'Raw Data'!$D$2:$D$92,Analysis_Commune!$D17,'Raw Data'!$N$2:$N$92,Analysis_Commune!E$4) -> 2 | F17: =COUNTIFS('Raw Data'!$I$2:$I$92,Analysis_Commune!$B17,'Raw Data'!$D$2:$D$92,Analysis_Commune!$D17,'Raw Data'!$N$2:$N$92,Analysis_Commune!F$4) -> 2
A18: Cas Cas / Saldé | B18: Mbolo Birane | C18: Tracteur | D18: Tractor | E18: =COUNTIFS('Raw Data'!$I$2:$I$92,Analysis_Commune!$B18,'Raw Data'!$D$2:$D$92,Analysis_Commune!$D18,'Raw Data'!$N$2:$N$92,Analysis_Commune!E$4) -> 0 | F18: =COUNTIFS('Raw Data'!$I$2:$I$92,Analysis_Commune!$B18,'Raw Data'!$D$2:$D$92,Analysis_Commune!$D18,'Raw Data'!$N$2:$N$92,Analysis_Commune!F$4) -> 1
A19: Cas Cas / Saldé | B19: Méry | C19: Tracteur | D19: Tractor | E19: =COUNTIFS('Raw Data'!$I$2:$I$92,Analysis_Commune!$B19,'Raw Data'!$D$2:$D$92,Analysis_Commune!$D19,'Raw Data'!$N$2:$N$92,Analysis_Commune!E$4) -> 1 | F19: =COUNTIFS('Raw Data'!$I$2:$I$92,Analysis_Commune!$B19,'Raw Data'!$D$2:$D$92,Analysis_Commune!$D19,'Raw Data'!$N$2:$N$92,Analysis_Commune!F$4) -> 0
A20: Cas Cas / Saldé | B20: Pété | C20: Tracteur | D20: Tractor | E20: =COUNTIFS('Raw Data'!$I$2:$I$92,Analysis_Commune!$B20,'Raw Data'!$D$2:$D$92,Analysis_Commune!$D20,'Raw Data'!$N$2:$N$92,Analysis_Commune!E$4) -> 1 | F20: =COUNTIFS('Raw Data'!$I$2:$I$92,Analysis_Commune!$B20,'Raw Data'!$D$2:$D$92,Analysis_Commune!$D20,'Raw Data'!$N$2:$N$92,Analysis_Commune!F$4) -> 0
A21: Cas Cas / Saldé | B21: Walaldé | C21: Tracteur | D21: Tractor | E21: =COUNTIFS('Raw Data'!$I$2:$I$92,Analysis_Commune!$B21,'Raw Data'!$D$2:$D$92,Analysis_Commune!$D21,'Raw Data'!$N$2:$N$92,Analysis_Commune!E$4) -> 0 | F21: =COUNTIFS('Raw Data'!$I$2:$I$92,Analysis_Commune!$B21,'Raw Data'!$D$2:$D$92,Analysis_Commune!$D21,'Raw Data'!$N$2:$N$92,Analysis_Commune!F$4) -> 1
A22: Cas Cas / Saldé | B22: Golléré | C22: Tracteur | D22: Tractor | E22: =COUNTIFS('Raw Data'!$I$2:$I$92,Analysis_Commune!$B22,'Raw Data'!$D$2:$D$92,Analysis_Commune!$D22,'Raw Data'!$N$2:$N$92,Analysis_Commune!E$4) -> 0 | F22: =COUNTIFS('Raw Data'!$I$2:$I$92,Analysis_Commune!$B22,'Raw Data'!$D$2:$D$92,Analysis_Commune!$D22,'Raw Data'!$N$2:$N$92,Analysis_Commune!F$4) -> 1
A23: Sous-total | E23: =SUM(E15:E22) -> 10 | F23: =SUM(F15:F22) -> 6
A24: Total | E24: =SUMIF($A5:$A23,"Sous-total",E5:E23) -> 58 | F24: =SUMIF($A5:$A23,"Sous-total",F5:F23) -> 11
A26: Nombre de moissonneuses-batteuses
A27: Secteur | B27: Commune | C27: Type materiel | D27: Type materiel | E27: Nombre de tracteurs
E28: Bon état | F28: Panne
E29: Function | F29: Breakdown
A30: Thillé Boubacar | B30: Fanaye | C30: Moissonneuses-batteuses | D30: Combine Harvester | E30: =COUNTIFS('Raw Data'!$I$2:$I$92,Analysis_Commune!$B30,'Raw Data'!$D$2:$D$92,Analysis_Commune!$D30,'Raw Data'!$N$2:$N$92,Analysis_Commune!E$4) -> 3 | F30: =COUNTIFS('Raw Data'!$I$2:$I$92,Analysis_Commune!$B30,'Raw Data'!$D$2:$D$92,Analysis_Commune!$D30,'Raw Data'!$N$2:$N$92,Analysis_Commune!F$4) -> 1
A31: Thillé Boubacar | B31: Ndiayenne Pendao | C31: Moissonneuses-batteuses | D31: Combine Harvester | E31: =COUNTIFS('Raw Data'!$I$2:$I$92,Analysis_Commune!$B31,'Raw Data'!$D$2:$D$92,Analysis_Commune!$D31,'Raw Data'!$N$2:$N$92,Analysis_Commune!E$4) -> 5 | F31: =COUNTIFS('Raw Data'!$I$2:$I$92,Analysis_Commune!$B31,'Raw Data'!$D$2:$D$92,Analysis_Commune!$D31,'Raw Data'!$N$2:$N$92,Analysis_Commune!F$4) -> 0
A32: Thillé Boubacar | B32: Niandane | C32: Moissonneuses-batteuses | D32: Combine Harvester | E32: =COUNTIFS('Raw Data'!$I$2:$I$92,Analysis_Commune!$B32,'Raw Data'!$D$2:$D$92,Analysis_Commune!$D32,'Raw Data'!$N$2:$N$92,Analysis_Commune!E$4) -> 1 | F32: =COUNTIFS('Raw Data'!$I$2:$I$92,Analysis_Commune!$B32,'Raw Data'!$D$2:$D$92,Analysis_Commune!$D32,'Raw Data'!$N$2:$N$92,Analysis_Commune!F$4) -> 2
A33: Sous-total | E33: =SUM(E30:E32) -> 9 | F33: =SUM(F30:F32) -> 3
A34: Gamadji Saré | B34: Démette | C34: Moissonneuses-batteuses | D34: Combine Harvester | E34: =COUNTIFS('Raw Data'!$I$2:$I$92,Analysis_Commune!$B34,'Raw Data'!$D$2:$D$92,Analysis_Commune!$D34,'Raw Data'!$N$2:$N$92,Analysis_Commune!E$4) -> 0 | F34: =COUNTIFS('Raw Data'!$I$2:$I$92,Analysis_Commune!$B34,'Raw Data'!$D$2:$D$92,Analysis_Commune!$D34,'Raw Data'!$N$2:$N$92,Analysis_Commune!F$4) -> 0
A35: Gamadji Saré | B35: Dodel | C35: Moissonneuses-batteuses | D35: Combine Harvester | E35: =COUNTIFS('Raw Data'!$I$2:$I$92,Analysis_Commune!$B35,'Raw Data'!$D$2:$D$92,Analysis_Commune!$D35,'Raw Data'!$N$2:$N$92,Analysis_Commune!E$4) -> 0 | F35: =COUNTIFS('Raw Data'!$I$2:$I$92,Analysis_Commune!$B35,'Raw Data'!$D$2:$D$92,Analysis_Commune!$D35,'Raw Data'!$N$2:$N$92,Analysis_Commune!F$4) -> 0
A36: Gamadji Saré | B36: Guede Village | C36: Moissonneuses-batteuses | D36: Combine Harvester | E36: =COUNTIFS('Raw Data'!$I$2:$I$92,Analysis_Commune!$B36,'Raw Data'!$D$2:$D$92,Analysis_Commune!$D36,'Raw Data'!$N$2:$N$92,Analysis_Commune!E$4) -> 5 | F36: =COUNTIFS('Raw Data'!$I$2:$I$92,Analysis_Commune!$B36,'Raw Data'!$D$2:$D$92,Analysis_Commune!$D36,'Raw Data'!$N$2:$N$92,Analysis_Commune!F$4) -> 0
A37: Gamadji Saré | B37: Ndioum | C37: Moissonneuses-batteuses | D37: Combine Harvester | E37: =COUNTIFS('Raw Data'!$I$2:$I$92,Analysis_Commune!$B37,'Raw Data'!$D$2:$D$92,Analysis_Commune!$D37,'Raw Data'!$N$2:$N$92,Analysis_Commune!E$4) -> 2 | F37: =COUNTIFS('Raw Data'!$I$2:$I$92,Analysis_Commune!$B37,'Raw Data'!$D$2:$D$92,Analysis_Commune!$D37,'Raw Data'!$N$2:$N$92,Analysis_Commune!F$4) -> 0
A38: Gamadji Saré | B38: Podor | C38: Moissonneuses-batteuses | D38: Combine Harvester | E38: =COUNTIFS('Raw Data'!$I$2:$I$92,Analysis_Commune!$B38,'Raw Data'!$D$2:$D$92,Analysis_Commune!$D38,'Raw Data'!$N$2:$N$92,Analysis_Commune!E$4) -> 0 | F38: =COUNTIFS('Raw Data'!$I$2:$I$92,Analysis_Commune!$B38,'Raw Data'!$D$2:$D$92,Analysis_Commune!$D38,'Raw Data'!$N$2:$N$92,Analysis_Commune!F$4) -> 0
A39: Sous-total | E39: =SUM(E34:E38) -> 7 | F39: =SUM(F34:F38) -> 0
A40: Cas Cas / Saldé | B40: Aéré Lao | C40: Moissonneuses-batteuses | D40: Combine Harvester | E40: =COUNTIFS('Raw Data'!$I$2:$I$92,Analysis_Commune!$B40,'Raw Data'!$D$2:$D$92,Analysis_Commune!$D40,'Raw Data'!$N$2:$N$92,Analysis_Commune!E$4) -> 2 | F40: =COUNTIFS('Raw Data'!$I$2:$I$92,Analysis_Commune!$B40,'Raw Data'!$D$2:$D$92,Analysis_Commune!$D40,'Raw Data'!$N$2:$N$92,Analysis_Commune!F$4) -> 0
A41: Cas Cas / Saldé | B41: Boké Dialloubé | C41: Moissonneuses-batteuses | D41: Combine Harvester | E41: =COUNTIFS('Raw Data'!$I$2:$I$92,Analysis_Commune!$B41,'Raw Data'!$D$2:$D$92,Analysis_Commune!$D41,'Raw Data'!$N$2:$N$92,Analysis_Commune!E$4) -> 0 | F41: =COUNTIFS('Raw Data'!$I$2:$I$92,Analysis_Commune!$B41,'Raw Data'!$D$2:$D$92,Analysis_Commune!$D41,'Raw Data'!$N$2:$N$92,Analysis_Commune!F$4) -> 0
...

Sheet List of Service Provider
P1: Tractor | S1: Combine Harvester | V1: Tractor | X1: Combine Harvester
A2: Delegation | B2: Secteur | C2: Caract materiels agricole | D2: type materiel | E2: Structure benef | F2: Type organisat | G2: Nom responsable | H2: Telephone | I2: commune_zi | J2: Arrondissement | K2: Année acquisition | L2: Provenance | M2: Financement | N2: Observations | P2: Service Provider (Extract) | Q2: Service Provider (List) | S2: Service Provider (Extract) | T2: Service Provider (List) | V2: List of Service provider | W2: Form | X2: List of Service provider | Y2: Form
A3: PODOR | B3: Cas Cas / Saldé | C3: Moissonneuse batteuse Massey Fergusson pneu | D3: Combine Harvester | E3: Union SP2 Aeré Lao | F3: Union | G3: Amadou Tidiane Dème | H3: 775567586 | I3: Aéré Lao | J3: Cas cas | K3: 2021 | L3: Fédération | M3: LBA | N3: Function | P3: {=IFERROR(_xlfn._xlws.FILTER(E3,D3="Tractor"),"")} | Q3: {=_xlfn.UNIQUE(P3:P93)} | S3: {=IFERROR(_xlfn._xlws.FILTER(E3,D3="Combine Harvester"),"")} -> Union SP2 Aeré Lao | T3: {=_xlfn.UNIQUE(S3:S93)} -> Union SP2 Aeré Lao | V3: PELLITAL (prestataire Aéré) | W3: =_xlfn.XLOOKUP(V3,$E$3:$E$93,$F$3:$F$93,"") -> Private | X3: Union SP2 Aeré Lao | Y3: =_xlfn.XLOOKUP(X3,$E$3:$E$93,$F$3:$F$93,"") -> Union
A4: PODOR | B4: Cas Cas / Saldé | C4: Tracteur 125CV+Offset 28 disques Jonh deer | D4: Tractor | E4: PELLITAL (prestataire Aéré) | F4: Private | G4: AMADOU THIAM | H4: 77 567 03 11 | I4: Aéré Lao | J4: Cas cas | K4: 2016 | L4: MAER | N4: Function | P4: {=IFERROR(_xlfn._xlws.FILTER(E4,D4="Tractor"),"")} -> PELLITAL (prestataire Aéré) | Q4: PELLITAL (prestataire Aéré) | S4: {=IFERROR(_xlfn._xlws.FILTER(E4,D4="Combine Harvester"),"")} | V4: Union des GIE de Aéré Lao SP 2 | W4: =_xlfn.XLOOKUP(V4,$E$3:$E$93,$F$3:$F$93,"") -> Union | X4: Union des GIE de Aéré Lao SP 2 | Y4: =_xlfn.XLOOKUP(X4,$E$3:$E$93,$F$3:$F$93,"") -> Union
A5: PODOR | B5: Cas Cas / Saldé | C5: Tracteur 100CV+Offset 24 disques Dushter et remorque 10 T | D5: Tractor | E5: Union des GIE de Aéré Lao SP 2 | F5: Union | G5: Amadou Tidiane Dème | H5: 77 556 75 86 | I5: Aéré Lao | J5: Cas cas | K5: 2024 | L5: MASAE | M5: LBA | N5: Function | P5: {=IFERROR(_xlfn._xlws.FILTER(E5,D5="Tractor"),"")} -> Union des GIE de Aéré Lao SP 2 | Q5: Union des GIE de Aéré Lao SP 2 | S5: {=IFERROR(_xlfn._xlws.FILTER(E5,D5="Combine Harvester"),"")} | T5: Union des GIE de Aéré Lao SP 2 | V5: GIE BIDIEW | W5: =_xlfn.XLOOKUP(V5,$E$3:$E$93,$F$3:$F$93,"") -> Private | X5: FUGIAM | Y5: =_xlfn.XLOOKUP(X5,$E$3:$E$93,$F$3:$F$93,"") -> Union
A6: PODOR | B6: Cas Cas / Saldé | C6: Moissonneuse batteuse à chenille FM WORLD | D6: Combine Harvester | E6: Union des GIE de Aéré Lao SP 2 | F6: Union | G6: Amadou Tidiane Dème | H6: 77 556 75 86 | I6: Aéré Lao | J6: Cas cas | K6: 2024 | L6: MASAE | M6: LBA | N6: Function | P6: {=IFERROR(_xlfn._xlws.FILTER(E6,D6="Tractor"),"")} | Q6: GIE BIDIEW | S6: {=IFERROR(_xlfn._xlws.FILTER(E6,D6="Combine Harvester"),"")} -> Union des GIE de Aéré Lao SP 2 | T6: FUGIAM | V6: UNION YIRLAABE THIKITE | W6: =_xlfn.XLOOKUP(V6,$E$3:$E$93,$F$3:$F$93,"") -> Union | X6: Union des Produceurs et Agriculteurs de Diatar | Y6: =_xlfn.XLOOKUP(X6,$E$3:$E$93,$F$3:$F$93,"") -> Union
A7: PODOR | B7: Cas Cas / Saldé | C7: Tracteur 100CV+Offset 24 disques | D7: Tractor | E7: GIE BIDIEW | F7: Private | G7: Thioye Fils | I7: Aéré Lao | J7: Cas cas | K7: 2019 | L7: MASAE | N7: Function | P7: {=IFERROR(_xlfn._xlws.FILTER(E7,D7="Tractor"),"")} -> GIE BIDIEW | Q7: UNION YIRLAABE THIKITE | S7: {=IFERROR(_xlfn._xlws.FILTER(E7,D7="Combine Harvester"),"")} | T7: Union des Produceurs et Agriculteurs de Diatar | V7: Union des GIE Yirlabé Saldé Ouallah | W7: =_xlfn.XLOOKUP(V7,$E$3:$E$93,$F$3:$F$93,"") -> Union | X7: Boumatt Agro fresh ABDOU SALL | Y7: =_xlfn.XLOOKUP(X7,$E$3:$E$93,$F$3:$F$93,"") -> Private
A8: PODOR | B8: Cas Cas / Saldé | C8: Tracteur 125CV+Offset 28 disques Jonh deer | D8: Tractor | E8: UNION YIRLAABE THIKITE | F8: Union | G8: CIRADJI BA | H8: 77 565 00 01 | I8: Boké Dialloubé | J8: Cas cas | K8: 2015 | L8: MAER | N8: Breakdown | P8: {=IFERROR(_xlfn._xlws.FILTER(E8,D8="Tractor"),"")} -> UNION YIRLAABE THIKITE | Q8: Union des GIE Yirlabé Saldé Ouallah | S8: {=IFERROR(_xlfn._xlws.FILTER(E8,D8="Combine Harvester"),"")} | T8: Boumatt Agro fresh ABDOU SALL | V8: UAI 4 SALDE | W8: =_xlfn.XLOOKUP(V8,$E$3:$E$93,$F$3:$F$93,"") -> Union | X8: GIE Diokere Endam MOUSSA HAROUNA LY | Y8: =_xlfn.XLOOKUP(X8,$E$3:$E$93,$F$3:$F$93,"") -> Private
A9: PODOR | B9: Cas Cas / Saldé | C9: Tracteur 100CV+Offset 24 disques Dushter et remorque 10 T | D9: Tractor | E9: Union des GIE Yirlabé Saldé Ouallah | F9: Union | H9: 77 519 26 44 | I9: Boké Dialloubé | J9: Saldé | K9: 2024 | L9: MASAE | N9: Function | P9: {=IFERROR(_xlfn._xlws.FILTER(E9,D9="Tractor"),"")} -> Union des GIE Yirlabé Saldé Ouallah | Q9: UAI 4 SALDE | S9: {=IFERROR(_xlfn._xlws.FILTER(E9,D9="Combine Harvester"),"")} | T9: GIE Diokere Endam MOUSSA HAROUNA LY | V9: UNION SALDE | W9: =_xlfn.XLOOKUP(V9,$E$3:$E$93,$F$3:$F$93,"") -> Union | X9: Fédération des GIE de Donaye | Y9: =_xlfn.XLOOKUP(X9,$E$3:$E$93,$F$3:$F$93,"") -> Union
A10: PODOR | B10: Cas Cas / Saldé | D10: Tractor | E10: UAI 4 SALDE | F10: Union | G10: ALLASANE DIA | H10: 774070332 | I10: Boké Dialloubé | J10: Saldé | K10: 2024 | L10: MASAE | M10: LBA | N10: Function | P10: {=IFERROR(_xlfn._xlws.FILTER(E10,D10="Tractor"),"")} -> UAI 4 SALDE | Q10: UNION SALDE | S10: {=IFERROR(_xlfn._xlws.FILTER(E10,D10="Combine Harvester"),"")} | T10: Fédération des GIE de Donaye | V10: Union de Cas-Cas | W10: =_xlfn.XLOOKUP(V10,$E$3:$E$93,$F$3:$F$93,"") -> Union | X10: Union des PIV de Guédé | Y10: =_xlfn.XLOOKUP(X10,$E$3:$E$93,$F$3:$F$93,"") -> Union
